Workbook

Sheet TABELA
C1: SAVEZ SPORTSKO RIBOLOVNIH ORGANIZACIJA CRNE GORE
C3: TABELA ŽRIJEBA
A6: Disciplina: Mušičarenje | E6: Datum: 27. 09. 2026. godine | H6: Mjesto održavanja: Rijeka Tara, Mojkovac | M6: Kolo: 5.
A8: ŠIFRA EKIPE | B8: NAZIV KLUBA | F8: GRUPA I | H8: GRUPA II | K8: GRUPA III
F9: Ime i prezime takmičara | H9: Ime i prezime takmičara | K9: Ime i prezime takmičara
A10: 1 | B10: SRK TARA - MOJKOVAC | F10: BOJAN GOVEDARICA | H10: BOGDAN GOVEDARICA | K10: SAVO RAIČEVIĆ
A11: 2 | B11: SRK GORŠTAK - KOLAŠIN | F11: VLATKO PEKOVIĆ | H11: MILJAN ANĐIĆ | K11: NIKOLA TREBJEŠANIN
A12: 3 | B12: SRK LIM - BERANE | F12: BOŠKO VULEVIĆ | H12: RADULE MIĆOVIĆ | K12: MILUN ĐUROVIĆ
A13: 4 | B13: SRK PLAVSKO JEZERO | F13: ORHAN BAŠIĆ | H13: OMAR BAŠIĆ | K13: DAMIR CANOVIĆ
A14: 5 | B14: SRFFK RAVNJAK - MOJKOVAC | F14: MILAN FUŠTIĆ | H14: BALŠA FUŠTIĆ | K14: ALEKSANDAR GAŠEVIĆ
A15: 6 | B15: SRFFK MANIRO - KOLAŠIN | F15: RADOVAN KRKOVIĆ | H15: GORAN OBRENOVIĆ | K15: BOGDAN MARKOVIĆ
A16: 7 | B16: SRK VODENE LISICE - PODGORICA | F16: NIKOLA ĐALOVIĆ | H16: PETAR OBRADOVIĆ | K16: MARKO BAKIĆ
A17: 8 | B17: SRK LIPLJEN - PLJEVLJA | F17: KEMAL AJANOVIĆ | H17: MEHMED DŽIDIĆ | K17: MUMIN HEKALO
A18: 9 | B18: SRK KOLAŠIN | F18: NIKOLA POPOVIĆ | H18: ARSO JEREMIĆ | K18: IVICA RAJKOVIĆ

Sheet GRUPA I
A1: GRUPA I PRVA SESIJA
A3: Redni broj | B3: Ime i Prezime | D3: Ime i Prezime | F3: Ime i Prezime | H3: Ime i Prezime | J3: Ime i Prezime | L3: Ime i Prezime | N3: Ime i Prezime | P3: Ime i Prezime | R3: Ime i Prezime
B4: =TABELA!F10 -> BOJAN GOVEDARICA | D4: =TABELA!F11 -> VLATKO PEKOVIĆ | F4: =TABELA!F12 -> BOŠKO VULEVIĆ | H4: =TABELA!F13 -> ORHAN BAŠIĆ | J4: =TABELA!F14 -> MILAN FUŠTIĆ | L4: =TABELA!F15 -> RADOVAN KRKOVIĆ | N4: =TABELA!F16 -> NIKOLA ĐALOVIĆ | P4: =TABELA!F17 -> KEMAL AJANOVIĆ | R4: =TABELA!F18 -> NIKOLA POPOVIĆ
B5: dužina-cm | C5: POENI | D5: dužina-cm | E5: POENI | F5: dužina-cm | G5: POENI | H5: dužina-cm | I5: POENI | J5: dužina-cm | K5: POENI | L5: dužina-cm | M5: POENI | N5: dužina-cm | O5: POENI | P5: dužina-cm | Q5: POENI | R5: dužina-cm | S5: POENI
A6: 1 | B6: 32 | C6: =IF(B6,B6*20+100,0) -> 740 | D6: 28 | E6: =IF(D6,D6*20+100,0) -> 660 | F6: 45 | G6: =IF(F6,F6*20+100,0) -> 1000 | I6: =IF(H6,H6*20+100,0) -> 0 | J6: 26 | K6: =IF(J6,J6*20+100,0) -> 620 | L6: 27 | M6: =IF(L6,L6*20+100,0) -> 640 | N6: 20 | O6: =IF(N6,N6*20+100,0) -> 500 | P6: 21 | Q6: =IF(P6,P6*20+100,0) -> 520 | S6: =IF(R6,R6*20+100,0) -> 0
A7: 2 | B7: 28 | C7: =IF(B7,B7*20+100,0) -> 660 | D7: 20 | E7: =IF(D7,D7*20+100,0) -> 500 | F7: 20 | G7: =IF(F7,F7*20+100,0) -> 500 | I7: =IF(H7,H7*20+100,0) -> 0 | J7: 21 | K7: =IF(J7,J7*20+100,0) -> 520 | L7: 25 | M7: =IF(L7,L7*20+100,0) -> 600 | N7: 27 | O7: =IF(N7,N7*20+100,0) -> 640 | Q7: =IF(P7,P7*20+100,0) -> 0 | S7: =IF(R7,R7*20+100,0) -> 0
A8: 3 | B8: 24 | C8: =IF(B8,B8*20+100,0) -> 580 | D8: 20 | E8: =IF(D8,D8*20+100,0) -> 500 | F8: 30 | G8: =IF(F8,F8*20+100,0) -> 700 | I8: =IF(H8,H8*20+100,0) -> 0 | J8: 30 | K8: =IF(J8,J8*20+100,0) -> 700 | M8: =IF(L8,L8*20+100,0) -> 0 | O8: =IF(N8,N8*20+100,0) -> 0 | Q8: =IF(P8,P8*20+100,0) -> 0 | S8: =IF(R8,R8*20+100,0) -> 0
A9: 4 | C9: =IF(B9,B9*20+100,0) -> 0 | D9: 29 | E9: =IF(D9,D9*20+100,0) -> 680 | G9: =IF(F9,F9*20+100,0) -> 0 | I9: =IF(H9,H9*20+100,0) -> 0 | J9: 28 | K9: =IF(J9,J9*20+100,0) -> 660 | M9: =IF(L9,L9*20+100,0) -> 0 | O9: =IF(N9,N9*20+100,0) -> 0 | Q9: =IF(P9,P9*20+100,0) -> 0 | S9: =IF(R9,R9*20+100,0) -> 0
A10: 5 | C10: =IF(B10,B10*20+100,0) -> 0 | E10: =IF(D10,D10*20+100,0) -> 0 | G10: =IF(F10,F10*20+100,0) -> 0 | I10: =IF(H10,H10*20+100,0) -> 0 | K10: =IF(J10,J10*20+100,0) -> 0 | M10: =IF(L10,L10*20+100,0) -> 0 | O10: =IF(N10,N10*20+100,0) -> 0 | Q10: =IF(P10,P10*20+100,0) -> 0 | S10: =IF(R10,R10*20+100,0) -> 0
A11: 6 | C11: =IF(B11,B11*20+100,0) -> 0 | E11: =IF(D11,D11*20+100,0) -> 0 | G11: =IF(F11,F11*20+100,0) -> 0 | I11: =IF(H11,H11*20+100,0) -> 0 | K11: =IF(J11,J11*20+100,0) -> 0 | M11: =IF(L11,L11*20+100,0) -> 0 | O11: =IF(N11,N11*20+100,0) -> 0 | Q11: =IF(P11,P11*20+100,0) -> 0 | S11: =IF(R11,R11*20+100,0) -> 0
A12: 7 | C12: =IF(B12,B12*20+100,0) -> 0 | E12: =IF(D12,D12*20+100,0) -> 0 | G12: =IF(F12,F12*20+100,0) -> 0 | I12: =IF(H12,H12*20+100,0) -> 0 | K12: =IF(J12,J12*20+100,0) -> 0 | M12: =IF(L12,L12*20+100,0) -> 0 | O12: =IF(N12,N12*20+100,0) -> 0 | Q12: =IF(P12,P12*20+100,0) -> 0 | S12: =IF(R12,R12*20+100,0) -> 0
A13: 8 | C13: =IF(B13,B13*20+100,0) -> 0 | E13: =IF(D13,D13*20+100,0) -> 0 | G13: =IF(F13,F13*20+100,0) -> 0 | I13: =IF(H13,H13*20+100,0) -> 0 | K13: =IF(J13,J13*20+100,0) -> 0 | M13: =IF(L13,L13*20+100,0) -> 0 | O13: =IF(N13,N13*20+100,0) -> 0 | Q13: =IF(P13,P13*20+100,0) -> 0 | S13: =IF(R13,R13*20+100,0) -> 0
A14: 9 | C14: =IF(B14,B14*20+100,0) -> 0 | E14: =IF(D14,D14*20+100,0) -> 0 | G14: =IF(F14,F14*20+100,0) -> 0 | I14: =IF(H14,H14*20+100,0) -> 0 | K14: =IF(J14,J14*20+100,0) -> 0 | M14: =IF(L14,L14*20+100,0) -> 0 | O14: =IF(N14,N14*20+100,0) -> 0 | Q14: =IF(P14,P14*20+100,0) -> 0 | S14: =IF(R14,R14*20+100,0) -> 0
A15: 10 | C15: =IF(B15,B15*20+100,0) -> 0 | E15: =IF(D15,D15*20+100,0) -> 0 | G15: =IF(F15,F15*20+100,0) -> 0 | I15: =IF(H15,H15*20+100,0) -> 0 | K15: =IF(J15,J15*20+100,0) -> 0 | M15: =IF(L15,L15*20+100,0) -> 0 | O15: =IF(N15,N15*20+100,0) -> 0 | Q15: =IF(P15,P15*20+100,0) -> 0 | S15: =IF(R15,R15*20+100,0) -> 0
A16: 11 | C16: =IF(B16,B16*20+100,0) -> 0 | E16: =IF(D16,D16*20+100,0) -> 0 | G16: =IF(F16,F16*20+100,0) -> 0 | I16: =IF(H16,H16*20+100,0) -> 0 | K16: =IF(J16,J16*20+100,0) -> 0 | M16: =IF(L16,L16*20+100,0) -> 0 | O16: =IF(N16,N16*20+100,0) -> 0 | Q16: =IF(P16,P16*20+100,0) -> 0 | S16: =IF(R16,R16*20+100,0) -> 0
A17: 12 | C17: =IF(B17,B17*20+100,0) -> 0 | E17: =IF(D17,D17*20+100,0) -> 0 | G17: =IF(F17,F17*20+100,0) -> 0 | I17: =IF(H17,H17*20+100,0) -> 0 | K17: =IF(J17,J17*20+100,0) -> 0 | M17: =IF(L17,L17*20+100,0) -> 0 | O17: =IF(N17,N17*20+100,0) -> 0 | Q17: =IF(P17,P17*20+100,0) -> 0 | S17: =IF(R17,R17*20+100,0) -> 0
A18: 13 | C18: =IF(B18,B18*20+100,0) -> 0 | E18: =IF(D18,D18*20+100,0) -> 0 | G18: =IF(F18,F18*20+100,0) -> 0 | I18: =IF(H18,H18*20+100,0) -> 0 | K18: =IF(J18,J18*20+100,0) -> 0 | M18: =IF(L18,L18*20+100,0) -> 0 | O18: =IF(N18,N18*20+100,0) -> 0 | Q18: =IF(P18,P18*20+100,0) -> 0 | S18: =IF(R18,R18*20+100,0) -> 0
A19: 14 | C19: =IF(B19,B19*20+100,0) -> 0 | E19: =IF(D19,D19*20+100,0) -> 0 | G19: =IF(F19,F19*20+100,0) -> 0 | I19: =IF(H19,H19*20+100,0) -> 0 | K19: =IF(J19,J19*20+100,0) -> 0 | M19: =IF(L19,L19*20+100,0) -> 0 | O19: =IF(N19,N19*20+100,0) -> 0 | Q19: =IF(P19,P19*20+100,0) -> 0 | S19: =IF(R19,R19*20+100,0) -> 0
A20: 15 | C20: =IF(B20,B20*20+100,0) -> 0 | E20: =IF(D20,D20*20+100,0) -> 0 | G20: =IF(F20,F20*20+100,0) -> 0 | I20: =IF(H20,H20*20+100,0) -> 0 | K20: =IF(J20,J20*20+100,0) -> 0 | M20: =IF(L20,L20*20+100,0) -> 0 | O20: =IF(N20,N20*20+100,0) -> 0 | Q20: =IF(P20,P20*20+100,0) -> 0 | S20: =IF(R20,R20*20+100,0) -> 0
A21: 16 | C21: =IF(B21,B21*20+100,0) -> 0 | E21: =IF(D21,D21*20+100,0) -> 0 | G21: =IF(F21,F21*20+100,0) -> 0 | I21: =IF(H21,H21*20+100,0) -> 0 | K21: =IF(J21,J21*20+100,0) -> 0 | M21: =IF(L21,L21*20+100,0) -> 0 | O21: =IF(N21,N21*20+100,0) -> 0 | Q21: =IF(P21,P21*20+100,0) -> 0 | S21: =IF(R21,R21*20+100,0) -> 0
... A35: 30 | C35: =IF(B35,B35*20+100,0) -> 0 | E35: =IF(D35,D35*20+100,0) -> 0 | G35: =IF(F35,F35*20+100,0) -> 0 | I35: =IF(H35,H35*20+100,0) -> 0 | K35: =IF(J35,J35*20+100,0) -> 0 | M35: =IF(L35,L35*20+100,0) -> 0 | O35: =IF(N35,N35*20+100,0) -> 0 | Q35: =IF(P35,P35*20+100,0) -> 0 | S35: =IF(R35,R35*20+100,0) -> 0
B36: UKUPNO POENA | C36: =SUM(C6:C35) -> 1980 | D36: UKUPNO POENA | E36: =SUM(E6:E35) -> 2340 | F36: UKUPNO POENA | G36: =SUM(G6:G35) -> 2200 | H36: UKUPNO POENA | I36: =SUM(I6:I35) -> 0 | J36: UKUPNO POENA | K36: =SUM(K6:K35) -> 2500 | L36: UKUPNO POENA | M36: =SUM(M6:M35) -> 1240 | N36: UKUPNO POENA | O36: =SUM(O6:O35) -> 1140 | P36: UKUPNO POENA | Q36: =SUM(Q6:Q35) -> 520 | R36: UKUPNO POENA | S36: =SUM(S6:S35) -> 0
B37: PLASMAN u ovoj sesiji | C37: =IF(C36=0,9,RANK(C36,$C$36:$S$36,0)) -> 4 | D37: PLASMAN u ovoj sesiji | E37: =IF(E36=0,9,RANK(E36,$C$36:$S$36,0)) -> 2 | F37: PLASMAN u ovoj sesiji | G37: =IF(G36=0,9,RANK(G36,$C$36:$S$36,0)) -> 3 | H37: PLASMAN u ovoj sesiji | I37: =IF(I36=0,9,RANK(I36,$C$36:$S$36,0)) -> 9 | J37: PLASMAN u ovoj sesiji | K37: =IF(K36=0,9,RANK(K36,$C$36:$S$36,0)) -> 1 | L37: PLASMAN u ovoj sesiji | M37: =IF(M36=0,9,RANK(M36,$C$36:$S$36,0)) -> 5 | N37: PLASMAN u ovoj sesiji | O37: =IF(O36=0,9,RANK(O36,$C$36:$S$36,0)) -> 6 | P37: PLASMAN u ovoj sesiji | Q37: =IF(Q36=0,9,RANK(Q36,$C$36:$S$36,0)) -> 7 | R37: PLASMAN u ovoj sesiji | S37: =IF(S36=0,9,RANK(S36,$C$36:$S$36,0)) -> 9
B38: UKUPNO RIBA | C38: =COUNT(B6:B35) -> 3 | D38: UKUPNO RIBA | E38: =COUNT(D6:D35) -> 4 | F38: UKUPNO RIBA | G38: =COUNT(F6:F35) -> 3 | H38: UKUPNO RIBA | I38: =COUNT(H6:H35) -> 0 | J38: UKUPNO RIBA | K38: =COUNT(J6:J35) -> 4 | L38: UKUPNO RIBA | M38: =COUNT(L6:L35) -> 2 | N38: UKUPNO RIBA | O38: =COUNT(N6:N35) -> 2 | P38: UKUPNO RIBA | Q38: =COUNT(P6:P35) -> 1 | R38: UKUPNO RIBA | S38: =COUNT(R6:R35) -> 0
B41: NAJDUŽA RIBA | C41: =MAX(B6:B35) -> 32 | D41: NAJDUŽA RIBA | E41: =MAX(D6:D35) -> 29 | F41: NAJDUŽA RIBA | G41: =MAX(F6:F35) -> 45 | H41: NAJDUŽA RIBA | I41: =MAX(H6:H35) -> 0 | J41: NAJDUŽA RIBA | K41: =MAX(J6:J35) -> 30 | L41: NAJDUŽA RIBA | M41: =MAX(L6:L35) -> 27 | N41: NAJDUŽA RIBA | O41: =MAX(N6:N35) -> 27 | P41: NAJDUŽA RIBA | Q41: =MAX(P6:P35) -> 21 | R41: NAJDUŽA RIBA | S41: =MAX(R6:R35) -> 0
A46: GRUPA I DRUGA SESIJA
A48: Redni broj | B48: Ime i Prezime | D48: Ime i Prezime | F48: Ime i Prezime | H48: Ime i Prezime | J48: Ime i Prezime | L48: Ime i Prezime | N48: Ime i Prezime | P48: Ime i Prezime | R48: Ime i Prezime
B49: =TABELA!F10 -> BOJAN GOVEDARICA | D49: =TABELA!F11 -> VLATKO PEKOVIĆ | F49: =TABELA!F12 -> BOŠKO VULEVIĆ | H49: =TABELA!F13 -> ORHAN BAŠIĆ | J49: =TABELA!F14 -> MILAN FUŠTIĆ | L49: =TABELA!F15 -> RADOVAN KRKOVIĆ | N49: =TABELA!F16 -> NIKOLA ĐALOVIĆ | P49: =TABELA!F17 -> KEMAL AJANOVIĆ | R49: =TABELA!F18 -> NIKOLA POPOVIĆ
B50: dužina-cm | C50: POENI | D50: dužina-cm | E50: POENI | F50: dužina-cm | G50: POENI | H50: dužina-cm | I50: POENI | J50: dužina-cm | K50: POENI | L50: dužina-cm | M50: POENI | N50: dužina-cm | O50: POENI | P50: dužina-cm | Q50: POENI | R50: dužina-cm | S50: POENI
A51: 1 | B51: 37 | C51: =IF(B51,B51*20+100,0) -> 840 | D51: 22 | E51: =IF(D51,D51*20+100,0) -> 540 | F51: 28 | G51: =IF(F51,F51*20+100,0) -> 660 | I51: =IF(H51,H51*20+100,0) -> 0 | J51: 28 | K51: =IF(J51,J51*20+100,0) -> 660 | L51: 35 | M51: =IF(L51,L51*20+100,0) -> 800 | O51: =IF(N51,N51*20+100,0) -> 0 | P51: 32 | Q51: =IF(P51,P51*20+100,0) -> 740 | R51: 29 | S51: =IF(R51,R51*20+100,0) -> 680
A52: 2 | B52: 20 | C52: =IF(B52,B52*20+100,0) -> 500 | D52: 27 | E52: =IF(D52,D52*20+100,0) -> 640 | G52: =IF(F52,F52*20+100,0) -> 0 | I52: =IF(H52,H52*20+100,0) -> 0 | K52: =IF(J52,J52*20+100,0) -> 0 | L52: 20 | M52: =IF(L52,L52*20+100,0) -> 500 | O52: =IF(N52,N52*20+100,0) -> 0 | P52: 25 | Q52: =IF(P52,P52*20+100,0) -> 600 | S52: =IF(R52,R52*20+100,0) -> 0
A53: 3 | B53: 21 | C53: =IF(B53,B53*20+100,0) -> 520 | D53: 32 | E53: =IF(D53,D53*20+100,0) -> 740 | G53: =IF(F53,F53*20+100,0) -> 0 | I53: =IF(H53,H53*20+100,0) -> 0 | K53: =IF(J53,J53*20+100,0) -> 0 | L53: 29 | M53: =IF(L53,L53*20+100,0) -> 680 | O53: =IF(N53,N53*20+100,0) -> 0 | Q53: =IF(P53,P53*20+100,0) -> 0 | S53: =IF(R53,R53*20+100,0) -> 0
A54: 4 | C54: =IF(B54,B54*20+100,0) -> 0 | D54: 28 | E54: =IF(D54,D54*20+100,0) -> 660 | G54: =IF(F54,F54*20+100,0) -> 0 | I54: =IF(H54,H54*20+100,0) -> 0 | K54: =IF(J54,J54*20+100,0) -> 0 | M54: =IF(L54,L54*20+100,0) -> 0 | O54: =IF(N54,N54*20+100,0) -> 0 | Q54: =IF(P54,P54*20+100,0) -> 0 | S54: =IF(R54,R54*20+100,0) -> 0
A55: 5 | C55: =IF(B55,B55*20+100,0) -> 0 | D55: 36 | E55: =IF(D55,D55*20+100,0) -> 820 | G55: =IF(F55,F55*20+100,0) -> 0 | I55: =IF(H55,H55*20+100,0) -> 0 | K55: =IF(J55,J55*20+100,0) -> 0 | M55: =IF(L55,L55*20+100,0) -> 0 | O55: =IF(N55,N55*20+100,0) -> 0 | Q55: =IF(P55,P55*20+100,0) -> 0 | S55: =IF(R55,R55*20+100,0) -> 0
A56: 6 | C56: =IF(B56,B56*20+100,0) -> 0 | E56: =IF(D56,D56*20+100,0) -> 0 | G56: =IF(F56,F56*20+100,0) -> 0 | I56: =IF(H56,H56*20+100,0) -> 0 | K56: =IF(J56,J56*20+100,0) -> 0 | M56: =IF(L56,L56*20+100,0) -> 0 | O56: =IF(N56,N56*20+100,0) -> 0 | Q56: =IF(P56,P56*20+100,0) -> 0 | S56: =IF(R56,R56*20+100,0) -> 0
A57: 7 | C57: =IF(B57,B57*20+100,0) -> 0 | E57: =IF(D57,D57*20+100,0) -> 0 | G57: =IF(F57,F57*20+100,0) -> 0 | I57: =IF(H57,H57*20+100,0) -> 0 | K57: =IF(J57,J57*20+100,0) -> 0 | M57: =IF(L57,L57*20+100,0) -> 0 | O57: =IF(N57,N57*20+100,0) -> 0 | Q57: =IF(P57,P57*20+100,0) -> 0 | S57: =IF(R57,R57*20+100,0) -> 0
A58: 8 | C58: =IF(B58,B58*20+100,0) -> 0 | E58: =IF(D58,D58*20+100,0) -> 0 | G58: =IF(F58,F58*20+100,0) -> 0 | I58: =IF(H58,H58*20+100,0) -> 0 | K58: =IF(J58,J58*20+100,0) -> 0 | M58: =IF(L58,L58*20+100,0) -> 0 | O58: =IF(N58,N58*20+100,0) -> 0 | Q58: =IF(P58,P58*20+100,0) -> 0 | S58: =IF(R58,R58*20+100,0) -> 0
A59: 9 | C59: =IF(B59,B59*20+100,0) -> 0 | E59: =IF(D59,D59*20+100,0) -> 0 | G59: =IF(F59,F59*20+100,0) -> 0 | I59: =IF(H59,H59*20+100,0) -> 0 | K59: =IF(J59,J59*20+100,0) -> 0 | M59: =IF(L59,L59*20+100,0) -> 0 | O59: =IF(N59,N59*20+100,0) -> 0 | Q59: =IF(P59,P59*20+100,0) -> 0 | S59: =IF(R59,R59*20+100,0) -> 0
A60: 10 | C60: =IF(B60,B60*20+100,0) -> 0 | E60: =IF(D60,D60*20+100,0) -> 0 | G60: =IF(F60,F60*20+100,0) -> 0 | I60: =IF(H60,H60*20+100,0) -> 0 | K60: =IF(J60,J60*20+100,0) -> 0 | M60: =IF(L60,L60*20+100,0) -> 0 | O60: =IF(N60,N60*20+100,0) -> 0 | Q60: =IF(P60,P60*20+100,0) -> 0 | S60: =IF(R60,R60*20+100,0) -> 0
A61: 11 | C61: =IF(B61,B61*20+100,0) -> 0 | E61: =IF(D61,D61*20+100,0) -> 0 | G61: =IF(F61,F61*20+100,0) -> 0 | I61: =IF(H61,H61*20+100,0) -> 0 | K61: =IF(J61,J61*20+100,0) -> 0 | M61: =IF(L61,L61*20+100,0) -> 0 | O61: =IF(N61,N61*20+100,0) -> 0 | Q61: =IF(P61,P61*20+100,0) -> 0 | S61: =IF(R61,R61*20+100,0) -> 0
...

Sheet GRUPA II
A1: GRUPA II PRVA SESIJA
A3: Redni broj | B3: Ime i Prezime | D3: Ime i Prezime | F3: Ime i Prezime | H3: Ime i Prezime | J3: Ime i Prezime | L3: Ime i Prezime | N3: Ime i Prezime | P3: Ime i Prezime | R3: Ime i Prezime
B4: =TABELA!H10 -> BOGDAN GOVEDARICA | D4: =TABELA!H11 -> MILJAN ANĐIĆ | F4: =TABELA!H12 -> RADULE MIĆOVIĆ | H4: =TABELA!H13 -> OMAR BAŠIĆ | J4: =TABELA!H14 -> BALŠA FUŠTIĆ | L4: =TABELA!H15 -> GORAN OBRENOVIĆ | N4: =TABELA!H16 -> PETAR OBRADOVIĆ | P4: =TABELA!H17 -> MEHMED DŽIDIĆ | R4: =TABELA!H18 -> ARSO JEREMIĆ
B5: dužina-cm | C5: POENI | D5: dužina-cm | E5: POENI | F5: dužina-cm | G5: POENI | H5: dužina-cm | I5: POENI | J5: dužina-cm | K5: POENI | L5: dužina-cm | M5: POENI | N5: dužina-cm | O5: POENI | P5: dužina-cm | Q5: POENI | R5: dužina-cm | S5: POENI
A6: 1 | C6: =IF(B6,B6*20+100,0) -> 0 | E6: =IF(D6,D6*20+100,0) -> 0 | F6: 35 | G6: =IF(F6,F6*20+100,0) -> 800 | H6: 31 | I6: =IF(H6,H6*20+100,0) -> 720 | J6: 27 | K6: =IF(J6,J6*20+100,0) -> 640 | L6: 21 | M6: =IF(L6,L6*20+100,0) -> 520 | N6: 22 | O6: =IF(N6,N6*20+100,0) -> 540 | P6: 31 | Q6: =IF(P6,P6*20+100,0) -> 720 | R6: 27 | S6: =IF(R6,R6*20+100,0) -> 640
A7: 2 | C7: =IF(B7,B7*20+100,0) -> 0 | E7: =IF(D7,D7*20+100,0) -> 0 | F7: 28 | G7: =IF(F7,F7*20+100,0) -> 660 | I7: =IF(H7,H7*20+100,0) -> 0 | K7: =IF(J7,J7*20+100,0) -> 0 | M7: =IF(L7,L7*20+100,0) -> 0 | O7: =IF(N7,N7*20+100,0) -> 0 | Q7: =IF(P7,P7*20+100,0) -> 0 | R7: 21 | S7: =IF(R7,R7*20+100,0) -> 520
A8: 3 | C8: =IF(B8,B8*20+100,0) -> 0 | E8: =IF(D8,D8*20+100,0) -> 0 | F8: 26 | G8: =IF(F8,F8*20+100,0) -> 620 | I8: =IF(H8,H8*20+100,0) -> 0 | K8: =IF(J8,J8*20+100,0) -> 0 | M8: =IF(L8,L8*20+100,0) -> 0 | O8: =IF(N8,N8*20+100,0) -> 0 | Q8: =IF(P8,P8*20+100,0) -> 0 | R8: 28 | S8: =IF(R8,R8*20+100,0) -> 660
A9: 4 | C9: =IF(B9,B9*20+100,0) -> 0 | E9: =IF(D9,D9*20+100,0) -> 0 | F9: 25 | G9: =IF(F9,F9*20+100,0) -> 600 | I9: =IF(H9,H9*20+100,0) -> 0 | K9: =IF(J9,J9*20+100,0) -> 0 | M9: =IF(L9,L9*20+100,0) -> 0 | O9: =IF(N9,N9*20+100,0) -> 0 | Q9: =IF(P9,P9*20+100,0) -> 0 | R9: 28 | S9: =IF(R9,R9*20+100,0) -> 660
A10: 5 | C10: =IF(B10,B10*20+100,0) -> 0 | E10: =IF(D10,D10*20+100,0) -> 0 | F10: 25 | G10: =IF(F10,F10*20+100,0) -> 600 | I10: =IF(H10,H10*20+100,0) -> 0 | K10: =IF(J10,J10*20+100,0) -> 0 | M10: =IF(L10,L10*20+100,0) -> 0 | O10: =IF(N10,N10*20+100,0) -> 0 | Q10: =IF(P10,P10*20+100,0) -> 0 | S10: =IF(R10,R10*20+100,0) -> 0
A11: 6 | C11: =IF(B11,B11*20+100,0) -> 0 | E11: =IF(D11,D11*20+100,0) -> 0 | G11: =IF(F11,F11*20+100,0) -> 0 | I11: =IF(H11,H11*20+100,0) -> 0 | K11: =IF(J11,J11*20+100,0) -> 0 | M11: =IF(L11,L11*20+100,0) -> 0 | O11: =IF(N11,N11*20+100,0) -> 0 | Q11: =IF(P11,P11*20+100,0) -> 0 | S11: =IF(R11,R11*20+100,0) -> 0
A12: 7 | C12: =IF(B12,B12*20+100,0) -> 0 | E12: =IF(D12,D12*20+100,0) -> 0 | G12: =IF(F12,F12*20+100,0) -> 0 | I12: =IF(H12,H12*20+100,0) -> 0 | K12: =IF(J12,J12*20+100,0) -> 0 | M12: =IF(L12,L12*20+100,0) -> 0 | O12: =IF(N12,N12*20+100,0) -> 0 | Q12: =IF(P12,P12*20+100,0) -> 0 | S12: =IF(R12,R12*20+100,0) -> 0
A13: 8 | C13: =IF(B13,B13*20+100,0) -> 0 | E13: =IF(D13,D13*20+100,0) -> 0 | G13: =IF(F13,F13*20+100,0) -> 0 | I13: =IF(H13,H13*20+100,0) -> 0 | K13: =IF(J13,J13*20+100,0) -> 0 | M13: =IF(L13,L13*20+100,0) -> 0 | O13: =IF(N13,N13*20+100,0) -> 0 | Q13: =IF(P13,P13*20+100,0) -> 0 | S13: =IF(R13,R13*20+100,0) -> 0
A14: 9 | C14: =IF(B14,B14*20+100,0) -> 0 | E14: =IF(D14,D14*20+100,0) -> 0 | G14: =IF(F14,F14*20+100,0) -> 0 | I14: =IF(H14,H14*20+100,0) -> 0 | K14: =IF(J14,J14*20+100,0) -> 0 | M14: =IF(L14,L14*20+100,0) -> 0 | O14: =IF(N14,N14*20+100,0) -> 0 | Q14: =IF(P14,P14*20+100,0) -> 0 | S14: =IF(R14,R14*20+100,0) -> 0
A15: 10 | C15: =IF(B15,B15*20+100,0) -> 0 | E15: =IF(D15,D15*20+100,0) -> 0 | G15: =IF(F15,F15*20+100,0) -> 0 | I15: =IF(H15,H15*20+100,0) -> 0 | K15: =IF(J15,J15*20+100,0) -> 0 | M15: =IF(L15,L15*20+100,0) -> 0 | O15: =IF(N15,N15*20+100,0) -> 0 | Q15: =IF(P15,P15*20+100,0) -> 0 | S15: =IF(R15,R15*20+100,0) -> 0
A16: 11 | C16: =IF(B16,B16*20+100,0) -> 0 | E16: =IF(D16,D16*20+100,0) -> 0 | G16: =IF(F16,F16*20+100,0) -> 0 | I16: =IF(H16,H16*20+100,0) -> 0 | K16: =IF(J16,J16*20+100,0) -> 0 | M16: =IF(L16,L16*20+100,0) -> 0 | O16: =IF(N16,N16*20+100,0) -> 0 | Q16: =IF(P16,P16*20+100,0) -> 0 | S16: =IF(R16,R16*20+100,0) -> 0
A17: 12 | C17: =IF(B17,B17*20+100,0) -> 0 | E17: =IF(D17,D17*20+100,0) -> 0 | G17: =IF(F17,F17*20+100,0) -> 0 | I17: =IF(H17,H17*20+100,0) -> 0 | K17: =IF(J17,J17*20+100,0) -> 0 | M17: =IF(L17,L17*20+100,0) -> 0 | O17: =IF(N17,N17*20+100,0) -> 0 | Q17: =IF(P17,P17*20+100,0) -> 0 | S17: =IF(R17,R17*20+100,0) -> 0
A18: 13 | C18: =IF(B18,B18*20+100,0) -> 0 | E18: =IF(D18,D18*20+100,0) -> 0 | G18: =IF(F18,F18*20+100,0) -> 0 | I18: =IF(H18,H18*20+100,0) -> 0 | K18: =IF(J18,J18*20+100,0) -> 0 | M18: =IF(L18,L18*20+100,0) -> 0 | O18: =IF(N18,N18*20+100,0) -> 0 | Q18: =IF(P18,P18*20+100,0) -> 0 | S18: =IF(R18,R18*20+100,0) -> 0
A19: 14 | C19: =IF(B19,B19*20+100,0) -> 0 | E19: =IF(D19,D19*20+100,0) -> 0 | G19: =IF(F19,F19*20+100,0) -> 0 | I19: =IF(H19,H19*20+100,0) -> 0 | K19: =IF(J19,J19*20+100,0) -> 0 | M19: =IF(L19,L19*20+100,0) -> 0 | O19: =IF(N19,N19*20+100,0) -> 0 | Q19: =IF(P19,P19*20+100,0) -> 0 | S19: =IF(R19,R19*20+100,0) -> 0
A20: 15 | C20: =IF(B20,B20*20+100,0) -> 0 | E20: =IF(D20,D20*20+100,0) -> 0 | G20: =IF(F20,F20*20+100,0) -> 0 | I20: =IF(H20,H20*20+100,0) -> 0 | K20: =IF(J20,J20*20+100,0) -> 0 | M20: =IF(L20,L20*20+100,0) -> 0 | O20: =IF(N20,N20*20+100,0) -> 0 | Q20: =IF(P20,P20*20+100,0) -> 0 | S20: =IF(R20,R20*20+100,0) -> 0
A21: 16 | C21: =IF(B21,B21*20+100,0) -> 0 | E21: =IF(D21,D21*20+100,0) -> 0 | G21: =IF(F21,F21*20+100,0) -> 0 | I21: =IF(H21,H21*20+100,0) -> 0 | K21: =IF(J21,J21*20+100,0) -> 0 | M21: =IF(L21,L21*20+100,0) -> 0 | O21: =IF(N21,N21*20+100,0) -> 0 | Q21: =IF(P21,P21*20+100,0) -> 0 | S21: =IF(R21,R21*20+100,0) -> 0
A22: 17 | C22: =IF(B22,B22*20+100,0) -> 0 | E22: =IF(D22,D22*20+100,0) -> 0 | G22: =IF(F22,F22*20+100,0) -> 0 | I22: =IF(H22,H22*20+100,0) -> 0 | K22: =IF(J22,J22*20+100,0) -> 0 | M22: =IF(L22,L22*20+100,0) -> 0 | O22: =IF(N22,N22*20+100,0) -> 0 | Q22: =IF(P22,P22*20+100,0) -> 0 | S22: =IF(R22,R22*20+100,0) -> 0
... A35: 30 | C35: =IF(B35,B35*20+100,0) -> 0 | E35: =IF(D35,D35*20+100,0) -> 0 | G35: =IF(F35,F35*20+100,0) -> 0 | I35: =IF(H35,H35*20+100,0) -> 0 | K35: =IF(J35,J35*20+100,0) -> 0 | M35: =IF(L35,L35*20+100,0) -> 0 | O35: =IF(N35,N35*20+100,0) -> 0 | Q35: =IF(P35,P35*20+100,0) -> 0 | S35: =IF(R35,R35*20+100,0) -> 0
B36: UKUPNO POENA | C36: =SUM(C6:C35) -> 0 | D36: UKUPNO POENA | E36: =SUM(E6:E35) -> 0 | F36: UKUPNO POENA | G36: =SUM(G6:G35) -> 3280 | H36: UKUPNO POENA | I36: =SUM(I6:I35) -> 720 | J36: UKUPNO POENA | K36: =SUM(K6:K35) -> 640 | L36: UKUPNO POENA | M36: =SUM(M6:M35) -> 520 | N36: UKUPNO POENA | O36: =SUM(O6:O35) -> 540 | P36: UKUPNO POENA | Q36: =SUM(Q6:Q35) -> 720 | R36: UKUPNO POENA | S36: =SUM(S6:S35) -> 2480
B37: PLASMAN u ovoj sesiji | C37: =IF(C36=0,9,RANK(C36,$C$36:$S$36,0)) -> 9 | D37: PLASMAN u ovoj sesiji | E37: =IF(E36=0,9,RANK(E36,$C$36:$S$36,0)) -> 9 | F37: PLASMAN u ovoj sesiji | G37: =IF(G36=0,9,RANK(G36,$C$36:$S$36,0)) -> 1 | H37: PLASMAN u ovoj sesiji | I37: =IF(I36=0,9,RANK(I36,$C$36:$S$36,0)) -> 3 | J37: PLASMAN u ovoj sesiji | K37: =IF(K36=0,9,RANK(K36,$C$36:$S$36,0)) -> 5 | L37: PLASMAN u ovoj sesiji | M37: =IF(M36=0,9,RANK(M36,$C$36:$S$36,0)) -> 7 | N37: PLASMAN u ovoj sesiji | O37: =IF(O36=0,9,RANK(O36,$C$36:$S$36,0)) -> 6 | P37: PLASMAN u ovoj sesiji | Q37: =IF(Q36=0,9,RANK(Q36,$C$36:$S$36,0)) -> 3 | R37: PLASMAN u ovoj sesiji | S37: =IF(S36=0,9,RANK(S36,$C$36:$S$36,0)) -> 2
B38: UKUPNO RIBA | C38: =COUNT(B6:B35) -> 0 | D38: UKUPNO RIBA | E38: =COUNT(D6:D35) -> 0 | F38: UKUPNO RIBA | G38: =COUNT(F6:F35) -> 5 | H38: UKUPNO RIBA | I38: =COUNT(H6:H35) -> 1 | J38: UKUPNO RIBA | K38: =COUNT(J6:J35) -> 1 | L38: UKUPNO RIBA | M38: =COUNT(L6:L35) -> 1 | N38: UKUPNO RIBA | O38: =COUNT(N6:N35) -> 1 | P38: UKUPNO RIBA | Q38: =COUNT(P6:P35) -> 1 | R38: UKUPNO RIBA | S38: =COUNT(R6:R35) -> 4
B41: NAJDUŽA RIBA | C41: =MAX(B6:B35) -> 0 | D41: NAJDUŽA RIBA | E41: =MAX(D6:D35) -> 0 | F41: NAJDUŽA RIBA | G41: =MAX(F6:F35) -> 35 | H41: NAJDUŽA RIBA | I41: =MAX(H6:H35) -> 31 | J41: NAJDUŽA RIBA | K41: =MAX(J6:J35) -> 27 | L41: NAJDUŽA RIBA | M41: =MAX(L6:L35) -> 21 | N41: NAJDUŽA RIBA | O41: =MAX(N6:N35) -> 22 | P41: NAJDUŽA RIBA | Q41: =MAX(P6:P35) -> 31 | R41: NAJDUŽA RIBA | S41: =MAX(R6:R35) -> 28
A45: GRUPA II DRUGA SESIJA
A47: Redni broj | B47: Ime i Prezime | D47: Ime i Prezime | F47: Ime i Prezime | H47: Ime i Prezime | J47: Ime i Prezime | L47: Ime i Prezime | N47: Ime i Prezime | P47: Ime i Prezime | R47: Ime i Prezime
B48: =TABELA!H10 -> BOGDAN GOVEDARICA | D48: =TABELA!H11 -> MILJAN ANĐIĆ | F48: =TABELA!H12 -> RADULE MIĆOVIĆ | H48: =TABELA!H13 -> OMAR BAŠIĆ | J48: =TABELA!H14 -> BALŠA FUŠTIĆ | L48: =TABELA!H15 -> GORAN OBRENOVIĆ | N48: =TABELA!H16 -> PETAR OBRADOVIĆ | P48: =TABELA!H17 -> MEHMED DŽIDIĆ | R48: =TABELA!H18 -> ARSO JEREMIĆ
B49: dužina-cm | C49: POENI | D49: dužina-cm | E49: POENI | F49: dužina-cm | G49: POENI | H49: dužina-cm | I49: POENI | J49: dužina-cm | K49: POENI | L49: dužina-cm | M49: POENI | N49: dužina-cm | O49: POENI | P49: dužina-cm | Q49: POENI | R49: dužina-cm | S49: POENI
A50: 1 | B50: 27 | C50: =IF(B50,B50*20+100,0) -> 640 | D50: 21 | E50: =IF(D50,D50*20+100,0) -> 520 | F50: 29 | G50: =IF(F50,F50*20+100,0) -> 680 | H50: 27 | I50: =IF(H50,H50*20+100,0) -> 640 | J50: 37 | K50: =IF(J50,J50*20+100,0) -> 840 | L50: 32 | M50: =IF(L50,L50*20+100,0) -> 740 | N50: 35 | O50: =IF(N50,N50*20+100,0) -> 800 | P50: 28 | Q50: =IF(P50,P50*20+100,0) -> 660 | R50: 33 | S50: =IF(R50,R50*20+100,0) -> 760
A51: 2 | B51: 21 | C51: =IF(B51,B51*20+100,0) -> 520 | E51: =IF(D51,D51*20+100,0) -> 0 | F51: 22 | G51: =IF(F51,F51*20+100,0) -> 540 | H51: 30 | I51: =IF(H51,H51*20+100,0) -> 700 | J51: 30 | K51: =IF(J51,J51*20+100,0) -> 700 | L51: 30 | M51: =IF(L51,L51*20+100,0) -> 700 | N51: 28 | O51: =IF(N51,N51*20+100,0) -> 660 | P51: 24 | Q51: =IF(P51,P51*20+100,0) -> 580 | S51: =IF(R51,R51*20+100,0) -> 0
A52: 3 | B52: 26 | C52: =IF(B52,B52*20+100,0) -> 620 | E52: =IF(D52,D52*20+100,0) -> 0 | F52: 29 | G52: =IF(F52,F52*20+100,0) -> 680 | I52: =IF(H52,H52*20+100,0) -> 0 | J52: 28 | K52: =IF(J52,J52*20+100,0) -> 660 | M52: =IF(L52,L52*20+100,0) -> 0 | N52: 27 | O52: =IF(N52,N52*20+100,0) -> 640 | P52: 28 | Q52: =IF(P52,P52*20+100,0) -> 660 | S52: =IF(R52,R52*20+100,0) -> 0
A53: 4 | C53: =IF(B53,B53*20+100,0) -> 0 | E53: =IF(D53,D53*20+100,0) -> 0 | G53: =IF(F53,F53*20+100,0) -> 0 | I53: =IF(H53,H53*20+100,0) -> 0 | K53: =IF(J53,J53*20+100,0) -> 0 | M53: =IF(L53,L53*20+100,0) -> 0 | N53: 29 | O53: =IF(N53,N53*20+100,0) -> 680 | P53: 27 | Q53: =IF(P53,P53*20+100,0) -> 640 | S53: =IF(R53,R53*20+100,0) -> 0
A54: 5 | C54: =IF(B54,B54*20+100,0) -> 0 | E54: =IF(D54,D54*20+100,0) -> 0 | G54: =IF(F54,F54*20+100,0) -> 0 | I54: =IF(H54,H54*20+100,0) -> 0 | K54: =IF(J54,J54*20+100,0) -> 0 | M54: =IF(L54,L54*20+100,0) -> 0 | N54: 32 | O54: =IF(N54,N54*20+100,0) -> 740 | Q54: =IF(P54,P54*20+100,0) -> 0 | S54: =IF(R54,R54*20+100,0) -> 0
A55: 6 | C55: =IF(B55,B55*20+100,0) -> 0 | E55: =IF(D55,D55*20+100,0) -> 0 | G55: =IF(F55,F55*20+100,0) -> 0 | I55: =IF(H55,H55*20+100,0) -> 0 | K55: =IF(J55,J55*20+100,0) -> 0 | M55: =IF(L55,L55*20+100,0) -> 0 | O55: =IF(N55,N55*20+100,0) -> 0 | Q55: =IF(P55,P55*20+100,0) -> 0 | S55: =IF(R55,R55*20+100,0) -> 0
A56: 7 | C56: =IF(B56,B56*20+100,0) -> 0 | E56: =IF(D56,D56*20+100,0) -> 0 | G56: =IF(F56,F56*20+100,0) -> 0 | I56: =IF(H56,H56*20+100,0) -> 0 | K56: =IF(J56,J56*20+100,0) -> 0 | M56: =IF(L56,L56*20+100,0) -> 0 | O56: =IF(N56,N56*20+100,0) -> 0 | Q56: =IF(P56,P56*20+100,0) -> 0 | S56: =IF(R56,R56*20+100,0) -> 0
A57: 8 | C57: =IF(B57,B57*20+100,0) -> 0 | E57: =IF(D57,D57*20+100,0) -> 0 | G57: =IF(F57,F57*20+100,0) -> 0 | I57: =IF(H57,H57*20+100,0) -> 0 | K57: =IF(J57,J57*20+100,0) -> 0 | M57: =IF(L57,L57*20+100,0) -> 0 | O57: =IF(N57,N57*20+100,0) -> 0 | Q57: =IF(P57,P57*20+100,0) -> 0 | S57: =IF(R57,R57*20+100,0) -> 0
A58: 9 | C58: =IF(B58,B58*20+100,0) -> 0 | E58: =IF(D58,D58*20+100,0) -> 0 | G58: =IF(F58,F58*20+100,0) -> 0 | I58: =IF(H58,H58*20+100,0) -> 0 | K58: =IF(J58,J58*20+100,0) -> 0 | M58: =IF(L58,L58*20+100,0) -> 0 | O58: =IF(N58,N58*20+100,0) -> 0 | Q58: =IF(P58,P58*20+100,0) -> 0 | S58: =IF(R58,R58*20+100,0) -> 0
A59: 10 | C59: =IF(B59,B59*20+100,0) -> 0 | E59: =IF(D59,D59*20+100,0) -> 0 | G59: =IF(F59,F59*20+100,0) -> 0 | I59: =IF(H59,H59*20+100,0) -> 0 | K59: =IF(J59,J59*20+100,0) -> 0 | M59: =IF(L59,L59*20+100,0) -> 0 | O59: =IF(N59,N59*20+100,0) -> 0 | Q59: =IF(P59,P59*20+100,0) -> 0 | S59: =IF(R59,R59*20+100,0) -> 0
...

Sheet GRUPA III
A1: GRUPA III PRVA SESIJA
A3: Redni broj | B3: Ime i Prezime | D3: Ime i Prezime | F3: Ime i Prezime | H3: Ime i Prezime | J3: Ime i Prezime | L3: Ime i Prezime | N3: Ime i Prezime | P3: Ime i Prezime | R3: Ime i Prezime
B4: =TABELA!K10 -> SAVO RAIČEVIĆ | D4: =TABELA!K11 -> NIKOLA TREBJEŠANIN | F4: =TABELA!K12 -> MILUN ĐUROVIĆ | H4: =TABELA!K13 -> DAMIR CANOVIĆ | J4: =TABELA!K14 -> ALEKSANDAR GAŠEVIĆ | L4: =TABELA!K15 -> BOGDAN MARKOVIĆ | N4: =TABELA!K16 -> MARKO BAKIĆ | P4: =TABELA!K17 -> MUMIN HEKALO | R4: =TABELA!K18 -> IVICA RAJKOVIĆ
B5: dužina-cm | C5: POENI | D5: dužina-cm | E5: POENI | F5: dužina-cm | G5: POENI | H5: dužina-cm | I5: POENI | J5: dužina-cm | K5: POENI | L5: dužina-cm | M5: POENI | N5: dužina-cm | O5: POENI | P5: dužina-cm | Q5: POENI | R5: dužina-cm | S5: POENI
A6: 1 | C6: =IF(B6,B6*20+100,0) -> 0 | D6: 27 | E6: =IF(D6,D6*20+100,0) -> 640 | F6: 24 | G6: =IF(F6,F6*20+100,0) -> 580 | H6: 21 | I6: =IF(H6,H6*20+100,0) -> 520 | J6: 30 | K6: =IF(J6,J6*20+100,0) -> 700 | L6: 43 | M6: =IF(L6,L6*20+100,0) -> 960 | O6: =IF(N6,N6*20+100,0) -> 0 | Q6: =IF(P6,P6*20+100,0) -> 0 | R6: 20 | S6: =IF(R6,R6*20+100,0) -> 500
A7: 2 | C7: =IF(B7,B7*20+100,0) -> 0 | E7: =IF(D7,D7*20+100,0) -> 0 | G7: =IF(F7,F7*20+100,0) -> 0 | I7: =IF(H7,H7*20+100,0) -> 0 | J7: 26 | K7: =IF(J7,J7*20+100,0) -> 620 | L7: 37 | M7: =IF(L7,L7*20+100,0) -> 840 | O7: =IF(N7,N7*20+100,0) -> 0 | Q7: =IF(P7,P7*20+100,0) -> 0 | R7: 20 | S7: =IF(R7,R7*20+100,0) -> 500
A8: 3 | C8: =IF(B8,B8*20+100,0) -> 0 | E8: =IF(D8,D8*20+100,0) -> 0 | G8: =IF(F8,F8*20+100,0) -> 0 | I8: =IF(H8,H8*20+100,0) -> 0 | J8: 30 | K8: =IF(J8,J8*20+100,0) -> 700 | M8: =IF(L8,L8*20+100,0) -> 0 | O8: =IF(N8,N8*20+100,0) -> 0 | Q8: =IF(P8,P8*20+100,0) -> 0 | R8: 29 | S8: =IF(R8,R8*20+100,0) -> 680
A9: 4 | C9: =IF(B9,B9*20+100,0) -> 0 | E9: =IF(D9,D9*20+100,0) -> 0 | G9: =IF(F9,F9*20+100,0) -> 0 | I9: =IF(H9,H9*20+100,0) -> 0 | J9: 26 | K9: =IF(J9,J9*20+100,0) -> 620 | M9: =IF(L9,L9*20+100,0) -> 0 | O9: =IF(N9,N9*20+100,0) -> 0 | Q9: =IF(P9,P9*20+100,0) -> 0 | R9: 28 | S9: =IF(R9,R9*20+100,0) -> 660
A10: 5 | C10: =IF(B10,B10*20+100,0) -> 0 | E10: =IF(D10,D10*20+100,0) -> 0 | G10: =IF(F10,F10*20+100,0) -> 0 | I10: =IF(H10,H10*20+100,0) -> 0 | J10: 30 | K10: =IF(J10,J10*20+100,0) -> 700 | M10: =IF(L10,L10*20+100,0) -> 0 | O10: =IF(N10,N10*20+100,0) -> 0 | Q10: =IF(P10,P10*20+100,0) -> 0 | R10: 28 | S10: =IF(R10,R10*20+100,0) -> 660
A11: 6 | C11: =IF(B11,B11*20+100,0) -> 0 | E11: =IF(D11,D11*20+100,0) -> 0 | G11: =IF(F11,F11*20+100,0) -> 0 | I11: =IF(H11,H11*20+100,0) -> 0 | J11: 23 | K11: =IF(J11,J11*20+100,0) -> 560 | M11: =IF(L11,L11*20+100,0) -> 0 | O11: =IF(N11,N11*20+100,0) -> 0 | Q11: =IF(P11,P11*20+100,0) -> 0 | R11: 20 | S11: =IF(R11,R11*20+100,0) -> 500
A12: 7 | C12: =IF(B12,B12*20+100,0) -> 0 | E12: =IF(D12,D12*20+100,0) -> 0 | G12: =IF(F12,F12*20+100,0) -> 0 | I12: =IF(H12,H12*20+100,0) -> 0 | J12: 22 | K12: =IF(J12,J12*20+100,0) -> 540 | M12: =IF(L12,L12*20+100,0) -> 0 | O12: =IF(N12,N12*20+100,0) -> 0 | Q12: =IF(P12,P12*20+100,0) -> 0 | S12: =IF(R12,R12*20+100,0) -> 0
A13: 8 | C13: =IF(B13,B13*20+100,0) -> 0 | E13: =IF(D13,D13*20+100,0) -> 0 | G13: =IF(F13,F13*20+100,0) -> 0 | I13: =IF(H13,H13*20+100,0) -> 0 | J13: 25 | K13: =IF(J13,J13*20+100,0) -> 600 | M13: =IF(L13,L13*20+100,0) -> 0 | O13: =IF(N13,N13*20+100,0) -> 0 | Q13: =IF(P13,P13*20+100,0) -> 0 | S13: =IF(R13,R13*20+100,0) -> 0
A14: 9 | C14: =IF(B14,B14*20+100,0) -> 0 | E14: =IF(D14,D14*20+100,0) -> 0 | G14: =IF(F14,F14*20+100,0) -> 0 | I14: =IF(H14,H14*20+100,0) -> 0 | K14: =IF(J14,J14*20+100,0) -> 0 | M14: =IF(L14,L14*20+100,0) -> 0 | O14: =IF(N14,N14*20+100,0) -> 0 | Q14: =IF(P14,P14*20+100,0) -> 0 | S14: =IF(R14,R14*20+100,0) -> 0
A15: 10 | C15: =IF(B15,B15*20+100,0) -> 0 | E15: =IF(D15,D15*20+100,0) -> 0 | G15: =IF(F15,F15*20+100,0) -> 0 | I15: =IF(H15,H15*20+100,0) -> 0 | K15: =IF(J15,J15*20+100,0) -> 0 | M15: =IF(L15,L15*20+100,0) -> 0 | O15: =IF(N15,N15*20+100,0) -> 0 | Q15: =IF(P15,P15*20+100,0) -> 0 | S15: =IF(R15,R15*20+100,0) -> 0
A16: 11 | C16: =IF(B16,B16*20+100,0) -> 0 | E16: =IF(D16,D16*20+100,0) -> 0 | G16: =IF(F16,F16*20+100,0) -> 0 | I16: =IF(H16,H16*20+100,0) -> 0 | K16: =IF(J16,J16*20+100,0) -> 0 | M16: =IF(L16,L16*20+100,0) -> 0 | O16: =IF(N16,N16*20+100,0) -> 0 | Q16: =IF(P16,P16*20+100,0) -> 0 | S16: =IF(R16,R16*20+100,0) -> 0
A17: 12 | C17: =IF(B17,B17*20+100,0) -> 0 | E17: =IF(D17,D17*20+100,0) -> 0 | G17: =IF(F17,F17*20+100,0) -> 0 | I17: =IF(H17,H17*20+100,0) -> 0 | K17: =IF(J17,J17*20+100,0) -> 0 | M17: =IF(L17,L17*20+100,0) -> 0 | O17: =IF(N17,N17*20+100,0) -> 0 | Q17: =IF(P17,P17*20+100,0) -> 0 | S17: =IF(R17,R17*20+100,0) -> 0
A18: 13 | C18: =IF(B18,B18*20+100,0) -> 0 | E18: =IF(D18,D18*20+100,0) -> 0 | G18: =IF(F18,F18*20+100,0) -> 0 | I18: =IF(H18,H18*20+100,0) -> 0 | K18: =IF(J18,J18*20+100,0) -> 0 | M18: =IF(L18,L18*20+100,0) -> 0 | O18: =IF(N18,N18*20+100,0) -> 0 | Q18: =IF(P18,P18*20+100,0) -> 0 | S18: =IF(R18,R18*20+100,0) -> 0
A19: 14 | C19: =IF(B19,B19*20+100,0) -> 0 | E19: =IF(D19,D19*20+100,0) -> 0 | G19: =IF(F19,F19*20+100,0) -> 0 | I19: =IF(H19,H19*20+100,0) -> 0 | K19: =IF(J19,J19*20+100,0) -> 0 | M19: =IF(L19,L19*20+100,0) -> 0 | O19: =IF(N19,N19*20+100,0) -> 0 | Q19: =IF(P19,P19*20+100,0) -> 0 | S19: =IF(R19,R19*20+100,0) -> 0
A20: 15 | C20: =IF(B20,B20*20+100,0) -> 0 | E20: =IF(D20,D20*20+100,0) -> 0 | G20: =IF(F20,F20*20+100,0) -> 0 | I20: =IF(H20,H20*20+100,0) -> 0 | K20: =IF(J20,J20*20+100,0) -> 0 | M20: =IF(L20,L20*20+100,0) -> 0 | O20: =IF(N20,N20*20+100,0) -> 0 | Q20: =IF(P20,P20*20+100,0) -> 0 | S20: =IF(R20,R20*20+100,0) -> 0
A21: 16 | C21: =IF(B21,B21*20+100,0) -> 0 | E21: =IF(D21,D21*20+100,0) -> 0 | G21: =IF(F21,F21*20+100,0) -> 0 | I21: =IF(H21,H21*20+100,0) -> 0 | K21: =IF(J21,J21*20+100,0) -> 0 | M21: =IF(L21,L21*20+100,0) -> 0 | O21: =IF(N21,N21*20+100,0) -> 0 | Q21: =IF(P21,P21*20+100,0) -> 0 | S21: =IF(R21,R21*20+100,0) -> 0
A22: 17 | C22: =IF(B22,B22*20+100,0) -> 0 | E22: =IF(D22,D22*20+100,0) -> 0 | G22: =IF(F22,F22*20+100,0) -> 0 | I22: =IF(H22,H22*20+100,0) -> 0 | K22: =IF(J22,J22*20+100,0) -> 0 | M22: =IF(L22,L22*20+100,0) -> 0 | O22: =IF(N22,N22*20+100,0) -> 0 | Q22: =IF(P22,P22*20+100,0) -> 0 | S22: =IF(R22,R22*20+100,0) -> 0
A23: 18 | C23: =IF(B23,B23*20+100,0) -> 0 | E23: =IF(D23,D23*20+100,0) -> 0 | G23: =IF(F23,F23*20+100,0) -> 0 | I23: =IF(H23,H23*20+100,0) -> 0 | K23: =IF(J23,J23*20+100,0) -> 0 | M23: =IF(L23,L23*20+100,0) -> 0 | O23: =IF(N23,N23*20+100,0) -> 0 | Q23: =IF(P23,P23*20+100,0) -> 0 | S23: =IF(R23,R23*20+100,0) -> 0
A24: 19 | C24: =IF(B24,B24*20+100,0) -> 0 | E24: =IF(D24,D24*20+100,0) -> 0 | G24: =IF(F24,F24*20+100,0) -> 0 | I24: =IF(H24,H24*20+100,0) -> 0 | K24: =IF(J24,J24*20+100,0) -> 0 | M24: =IF(L24,L24*20+100,0) -> 0 | O24: =IF(N24,N24*20+100,0) -> 0 | Q24: =IF(P24,P24*20+100,0) -> 0 | S24: =IF(R24,R24*20+100,0) -> 0
A25: 20 | C25: =IF(B25,B25*20+100,0) -> 0 | E25: =IF(D25,D25*20+100,0) -> 0 | G25: =IF(F25,F25*20+100,0) -> 0 | I25: =IF(H25,H25*20+100,0) -> 0 | K25: =IF(J25,J25*20+100,0) -> 0 | M25: =IF(L25,L25*20+100,0) -> 0 | O25: =IF(N25,N25*20+100,0) -> 0 | Q25: =IF(P25,P25*20+100,0) -> 0 | S25: =IF(R25,R25*20+100,0) -> 0
... A35: 30 | C35: =IF(B35,B35*20+100,0) -> 0 | E35: =IF(D35,D35*20+100,0) -> 0 | G35: =IF(F35,F35*20+100,0) -> 0 | I35: =IF(H35,H35*20+100,0) -> 0 | K35: =IF(J35,J35*20+100,0) -> 0 | M35: =IF(L35,L35*20+100,0) -> 0 | O35: =IF(N35,N35*20+100,0) -> 0 | Q35: =IF(P35,P35*20+100,0) -> 0 | S35: =IF(R35,R35*20+100,0) -> 0
B36: UKUPNO POENA | C36: =SUM(C6:C35) -> 0 | D36: UKUPNO POENA | E36: =SUM(E6:E35) -> 640 | F36: UKUPNO POENA | G36: =SUM(G6:G35) -> 580 | H36: UKUPNO POENA | I36: =SUM(I6:I35) -> 520 | J36: UKUPNO POENA | K36: =SUM(K6:K35) -> 5040 | L36: UKUPNO POENA | M36: =SUM(M6:M35) -> 1800 | N36: UKUPNO POENA | O36: =SUM(O6:O35) -> 0 | P36: UKUPNO POENA | Q36: =SUM(Q6:Q35) -> 0 | R36: UKUPNO POENA | S36: =SUM(S6:S35) -> 3500
B37: PLASMAN u ovoj sesiji | C37: =IF(C36=0,9,RANK(C36,$C$36:$S$36,0)) -> 9 | D37: PLASMAN u ovoj sesiji | E37: =IF(E36=0,9,RANK(E36,$C$36:$S$36,0)) -> 4 | F37: PLASMAN u ovoj sesiji | G37: =IF(G36=0,9,RANK(G36,$C$36:$S$36,0)) -> 5 | H37: PLASMAN u ovoj sesiji | I37: =IF(I36=0,9,RANK(I36,$C$36:$S$36,0)) -> 6 | J37: PLASMAN u ovoj sesiji | K37: =IF(K36=0,9,RANK(K36,$C$36:$S$36,0)) -> 1 | L37: PLASMAN u ovoj sesiji | M37: =IF(M36=0,9,RANK(M36,$C$36:$S$36,0)) -> 3 | N37: PLASMAN u ovoj sesiji | O37: =IF(O36=0,9,RANK(O36,$C$36:$S$36,0)) -> 9 | P37: PLASMAN u ovoj sesiji | Q37: =IF(Q36=0,9,RANK(Q36,$C$36:$S$36,0)) -> 9 | R37: PLASMAN u ovoj sesiji | S37: =IF(S36=0,9,RANK(S36,$C$36:$S$36,0)) -> 2
B38: UKUPNO RIBA | C38: =COUNT(B6:B35) -> 0 | D38: UKUPNO RIBA | E38: =COUNT(D6:D35) -> 1 | F38: UKUPNO RIBA | G38: =COUNT(F6:F35) -> 1 | H38: UKUPNO RIBA | I38: =COUNT(H6:H35) -> 1 | J38: UKUPNO RIBA | K38: =COUNT(J6:J35) -> 8 | L38: UKUPNO RIBA | M38: =COUNT(L6:L35) -> 2 | N38: UKUPNO RIBA | O38: =COUNT(N6:N35) -> 0 | P38: UKUPNO RIBA | Q38: =COUNT(P6:P35) -> 0 | R38: UKUPNO RIBA | S38: =COUNT(R6:R35) -> 6
B41: NAJDUŽA RIBA | C41: =MAX(B6:B35) -> 0 | D41: NAJDUŽA RIBA | E41: =MAX(D6:D35) -> 27 | F41: NAJDUŽA RIBA | G41: =MAX(F6:F35) -> 24 | H41: NAJDUŽA RIBA | I41: =MAX(H6:H35) -> 21 | J41: NAJDUŽA RIBA | K41: =MAX(J6:J35) -> 30 | L41: NAJDUŽA RIBA | M41: =MAX(L6:L35) -> 43 | N41: NAJDUŽA RIBA | O41: =MAX(N6:N35) -> 0 | P41: NAJDUŽA RIBA | Q41: =MAX(P6:P35) -> 0 | R41: NAJDUŽA RIBA | S41: =MAX(R6:R35) -> 29
A45: GRUPA III DRUGA SESIJA
A47: Redni broj | B47: Ime i Prezime | D47: Ime i Prezime | F47: Ime i Prezime | H47: Ime i Prezime | J47: Ime i Prezime | L47: Ime i Prezime | N47: Ime i Prezime | P47: Ime i Prezime | R47: Ime i Prezime
B48: =TABELA!K10 -> SAVO RAIČEVIĆ | D48: =TABELA!K11 -> NIKOLA TREBJEŠANIN | F48: =TABELA!K12 -> MILUN ĐUROVIĆ | H48: =TABELA!K13 -> DAMIR CANOVIĆ | J48: =TABELA!K14 -> ALEKSANDAR GAŠEVIĆ | L48: =TABELA!K15 -> BOGDAN MARKOVIĆ | N48: =TABELA!K16 -> MARKO BAKIĆ | P48: =TABELA!K17 -> MUMIN HEKALO | R48: =TABELA!K18 -> IVICA RAJKOVIĆ
B49: dužina-cm | C49: POENI | D49: dužina-cm | E49: POENI | F49: dužina-cm | G49: POENI | H49: dužina-cm | I49: POENI | J49: dužina-cm | K49: POENI | L49: dužina-cm | M49: POENI | N49: dužina-cm | O49: POENI | P49: dužina-cm | Q49: POENI | R49: dužina-cm | S49: POENI
A50: 1 | B50: 43 | C50: =IF(B50,B50*20+100,0) -> 960 | D50: 25 | E50: =IF(D50,D50*20+100,0) -> 600 | F50: 29 | G50: =IF(F50,F50*20+100,0) -> 680 | H50: 23 | I50: =IF(H50,H50*20+100,0) -> 560 | J50: 20 | K50: =IF(J50,J50*20+100,0) -> 500 | L50: 27 | M50: =IF(L50,L50*20+100,0) -> 640 | N50: 28 | O50: =IF(N50,N50*20+100,0) -> 660 | P50: 34 | Q50: =IF(P50,P50*20+100,0) -> 780 | R50: 32 | S50: =IF(R50,R50*20+100,0) -> 740
A51: 2 | C51: =IF(B51,B51*20+100,0) -> 0 | E51: =IF(D51,D51*20+100,0) -> 0 | F51: 37 | G51: =IF(F51,F51*20+100,0) -> 840 | I51: =IF(H51,H51*20+100,0) -> 0 | J51: 23 | K51: =IF(J51,J51*20+100,0) -> 560 | M51: =IF(L51,L51*20+100,0) -> 0 | N51: 25 | O51: =IF(N51,N51*20+100,0) -> 600 | Q51: =IF(P51,P51*20+100,0) -> 0 | R51: 30 | S51: =IF(R51,R51*20+100,0) -> 700
A52: 3 | C52: =IF(B52,B52*20+100,0) -> 0 | E52: =IF(D52,D52*20+100,0) -> 0 | F52: 31 | G52: =IF(F52,F52*20+100,0) -> 720 | I52: =IF(H52,H52*20+100,0) -> 0 | J52: 30 | K52: =IF(J52,J52*20+100,0) -> 700 | M52: =IF(L52,L52*20+100,0) -> 0 | N52: 29 | O52: =IF(N52,N52*20+100,0) -> 680 | Q52: =IF(P52,P52*20+100,0) -> 0 | S52: =IF(R52,R52*20+100,0) -> 0
A53: 4 | C53: =IF(B53,B53*20+100,0) -> 0 | E53: =IF(D53,D53*20+100,0) -> 0 | F53: 24 | G53: =IF(F53,F53*20+100,0) -> 580 | I53: =IF(H53,H53*20+100,0) -> 0 | J53: 25 | K53: =IF(J53,J53*20+100,0) -> 600 | M53: =IF(L53,L53*20+100,0) -> 0 | N53: 27 | O53: =IF(N53,N53*20+100,0) -> 640 | Q53: =IF(P53,P53*20+100,0) -> 0 | S53: =IF(R53,R53*20+100,0) -> 0
A54: 5 | C54: =IF(B54,B54*20+100,0) -> 0 | E54: =IF(D54,D54*20+100,0) -> 0 | F54: 27 | G54: =IF(F54,F54*20+100,0) -> 640 | I54: =IF(H54,H54*20+100,0) -> 0 | K54: =IF(J54,J54*20+100,0) -> 0 | M54: =IF(L54,L54*20+100,0) -> 0 | O54: =IF(N54,N54*20+100,0) -> 0 | Q54: =IF(P54,P54*20+100,0) -> 0 | S54: =IF(R54,R54*20+100,0) -> 0
A55: 6 | C55: =IF(B55,B55*20+100,0) -> 0 | E55: =IF(D55,D55*20+100,0) -> 0 | G55: =IF(F55,F55*20+100,0) -> 0 | I55: =IF(H55,H55*20+100,0) -> 0 | K55: =IF(J55,J55*20+100,0) -> 0 | M55: =IF(L55,L55*20+100,0) -> 0 | O55: =IF(N55,N55*20+100,0) -> 0 | Q55: =IF(P55,P55*20+100,0) -> 0 | S55: =IF(R55,R55*20+100,0) -> 0
A56: 7 | C56: =IF(B56,B56*20+100,0) -> 0 | E56: =IF(D56,D56*20+100,0) -> 0 | G56: =IF(F56,F56*20+100,0) -> 0 | I56: =IF(H56,H56*20+100,0) -> 0 | K56: =IF(J56,J56*20+100,0) -> 0 | M56: =IF(L56,L56*20+100,0) -> 0 | O56: =IF(N56,N56*20+100,0) -> 0 | Q56: =IF(P56,P56*20+100,0) -> 0 | S56: =IF(R56,R56*20+100,0) -> 0
...

Sheet POJEDINACNO
A2: MUŠIČARSKA LIGA CRNE GORE UKUPAN PLASMAN - PRVO KOLO
A4: Redni broj | B4: IME I PREZIME | F4: NAZIV KLUBA | I4: SESIJA I | K4: SESIJA II | M4: SESIJA III | O4: UKUPNO | Q4: UKUPAN PLASMAN
I5: Poena I sesija | J5: Sektorski Plasman | K5: Poena II sesija | L5: Sektorski Plasman | M5: Poena III sesija | N5: Sektorski Plasman | O5: UKUPNO POENA | P5: ZBIR SEKTORSKIH PLASMANA
A7: 1 | B7: =TABELA!F10 -> BOJAN GOVEDARICA | F7: =TABELA!B10 -> SRK TARA - MOJKOVAC | I7: ='GRUPA I'!C36 -> 1980 | J7: ='GRUPA I'!C37 -> 4 | K7: ='GRUPA I'!C81 -> 1860 | L7: ='GRUPA I'!C82 -> 3 | M7: ='GRUPA I'!C124 -> 1860 | N7: ='GRUPA I'!C125 -> 5 | O7: =(I7+K7+M7) -> 5700 | P7: =(J7+L7+N7) -> 12 | Q7: =RANK(P7,$P$7:$P$33,1)+COUNTIFS($P$7:$P$33,P7,$O$7:$O$33,">"&O7) -> 8
A8: 2 | B8: =TABELA!F11 -> VLATKO PEKOVIĆ | F8: =TABELA!B11 -> SRK GORŠTAK - KOLAŠIN | I8: ='GRUPA I'!E36 -> 2340 | J8: ='GRUPA I'!E37 -> 2 | K8: ='GRUPA I'!E81 -> 3400 | L8: ='GRUPA I'!E82 -> 1 | M8: ='GRUPA I'!E124 -> 1260 | N8: ='GRUPA I'!E125 -> 8 | O8: =(I8+K8+M8) -> 7000 | P8: =(J8+L8+N8) -> 11 | Q8: =RANK(P8,$P$7:$P$33,1)+COUNTIFS($P$7:$P$33,P8,$O$7:$O$33,">"&O8) -> 6
A9: 3 | B9: =TABELA!F12 -> BOŠKO VULEVIĆ | F9: =TABELA!B12 -> SRK LIM - BERANE | I9: ='GRUPA I'!G36 -> 2200 | J9: ='GRUPA I'!G37 -> 3 | K9: ='GRUPA I'!G81 -> 660 | L9: ='GRUPA I'!G82 -> 6 | M9: ='GRUPA I'!G124 -> 1980 | N9: ='GRUPA I'!G125 -> 3 | O9: =(I9+K9+M9) -> 4840 | P9: =(J9+L9+N9) -> 12 | Q9: =RANK(P9,$P$7:$P$33,1)+COUNTIFS($P$7:$P$33,P9,$O$7:$O$33,">"&O9) -> 9
A10: 4 | B10: =TABELA!F13 -> ORHAN BAŠIĆ | F10: =TABELA!B13 -> SRK PLAVSKO JEZERO | I10: ='GRUPA I'!I36 -> 0 | J10: ='GRUPA I'!I37 -> 9 | K10: ='GRUPA I'!I81 -> 0 | L10: ='GRUPA I'!I82 -> 9 | M10: ='GRUPA I'!I124 -> 0 | N10: ='GRUPA I'!I125 -> 9 | O10: =(I10+K10+M10) -> 0 | P10: =(J10+L10+N10) -> 27 | Q10: =RANK(P10,$P$7:$P$33,1)+COUNTIFS($P$7:$P$33,P10,$O$7:$O$33,">"&O10) -> 27
A11: 5 | B11: =TABELA!F14 -> MILAN FUŠTIĆ | F11: =TABELA!B14 -> SRFFK RAVNJAK - MOJKOVAC | I11: ='GRUPA I'!K36 -> 2500 | J11: ='GRUPA I'!K37 -> 1 | K11: ='GRUPA I'!K81 -> 660 | L11: ='GRUPA I'!K82 -> 6 | M11: ='GRUPA I'!K124 -> 1360 | N11: ='GRUPA I'!K125 -> 7 | O11: =(I11+K11+M11) -> 4520 | P11: =(J11+L11+N11) -> 14 | Q11: =RANK(P11,$P$7:$P$33,1)+COUNTIFS($P$7:$P$33,P11,$O$7:$O$33,">"&O11) -> 13
A12: 6 | B12: =TABELA!F15 -> RADOVAN KRKOVIĆ | F12: =TABELA!B15 -> SRFFK MANIRO - KOLAŠIN | I12: ='GRUPA I'!M36 -> 1240 | J12: ='GRUPA I'!M37 -> 5 | K12: ='GRUPA I'!M81 -> 1980 | L12: ='GRUPA I'!M82 -> 2 | M12: ='GRUPA I'!M124 -> 4780 | N12: ='GRUPA I'!M125 -> 1 | O12: =(I12+K12+M12) -> 8000 | P12: =(J12+L12+N12) -> 8 | Q12: =RANK(P12,$P$7:$P$33,1)+COUNTIFS($P$7:$P$33,P12,$O$7:$O$33,">"&O12) -> 4
A13: 7 | B13: =TABELA!F16 -> NIKOLA ĐALOVIĆ | F13: =TABELA!B16 -> SRK VODENE LISICE - PODGORICA | I13: ='GRUPA I'!O36 -> 1140 | J13: ='GRUPA I'!O37 -> 6 | K13: ='GRUPA I'!O81 -> 0 | L13: ='GRUPA I'!O82 -> 9 | M13: ='GRUPA I'!O124 -> 1960 | N13: ='GRUPA I'!O125 -> 4 | O13: =(I13+K13+M13) -> 3100 | P13: =(J13+L13+N13) -> 19 | Q13: =RANK(P13,$P$7:$P$33,1)+COUNTIFS($P$7:$P$33,P13,$O$7:$O$33,">"&O13) -> 20
A14: 8 | B14: =TABELA!F17 -> KEMAL AJANOVIĆ | F14: =TABELA!B17 -> SRK LIPLJEN - PLJEVLJA | I14: ='GRUPA I'!Q36 -> 520 | J14: ='GRUPA I'!Q37 -> 7 | K14: ='GRUPA I'!Q81 -> 1340 | L14: ='GRUPA I'!Q82 -> 4 | M14: ='GRUPA I'!Q124 -> 1700 | N14: ='GRUPA I'!Q125 -> 6 | O14: =(I14+K14+M14) -> 3560 | P14: =(J14+L14+N14) -> 17 | Q14: =RANK(P14,$P$7:$P$33,1)+COUNTIFS($P$7:$P$33,P14,$O$7:$O$33,">"&O14) -> 18
A15: 9 | B15: =TABELA!F18 -> NIKOLA POPOVIĆ | F15: =TABELA!B18 -> SRK KOLAŠIN | I15: ='GRUPA I'!S36 -> 0 | J15: ='GRUPA I'!S37 -> 9 | K15: ='GRUPA I'!S81 -> 680 | L15: ='GRUPA I'!S82 -> 5 | M15: ='GRUPA I'!S124 -> 2420 | N15: ='GRUPA I'!S125 -> 2 | O15: =(I15+K15+M15) -> 3100 | P15: =(J15+L15+N15) -> 16 | Q15: =RANK(P15,$P$7:$P$33,1)+COUNTIFS($P$7:$P$33,P15,$O$7:$O$33,">"&O15) -> 17
A16: 10 | B16: =TABELA!H10 -> BOGDAN GOVEDARICA | F16: =TABELA!B10 -> SRK TARA - MOJKOVAC | I16: ='GRUPA II'!C36 -> 0 | J16: ='GRUPA II'!C37 -> 9 | K16: ='GRUPA II'!C80 -> 1780 | L16: ='GRUPA II'!C81 -> 5 | M16: ='GRUPA II'!C124 -> 0 | N16: ='GRUPA II'!C126 -> 9 | O16: =(I16+K16+M16) -> 1780 | P16: =(J16+L16+N16) -> 23 | Q16: =RANK(P16,$P$7:$P$33,1)+COUNTIFS($P$7:$P$33,P16,$O$7:$O$33,">"&O16) -> 24
A17: 11 | B17: =TABELA!H11 -> MILJAN ANĐIĆ | F17: =TABELA!B11 -> SRK GORŠTAK - KOLAŠIN | I17: ='GRUPA II'!E36 -> 0 | J17: ='GRUPA II'!E37 -> 9 | K17: ='GRUPA II'!E80 -> 520 | L17: ='GRUPA II'!E81 -> 9 | M17: ='GRUPA II'!E124 -> 0 | N17: ='GRUPA II'!E126 -> 9 | O17: =(I17+K17+M17) -> 520 | P17: =(J17+L17+N17) -> 27 | Q17: =RANK(P17,$P$7:$P$33,1)+COUNTIFS($P$7:$P$33,P17,$O$7:$O$33,">"&O17) -> 26
A18: 12 | B18: =TABELA!H12 -> RADULE MIĆOVIĆ | F18: =TABELA!B12 -> SRK LIM - BERANE | I18: ='GRUPA II'!G36 -> 3280 | J18: ='GRUPA II'!G37 -> 1 | K18: ='GRUPA II'!G80 -> 1900 | L18: ='GRUPA II'!G81 -> 4 | M18: ='GRUPA II'!G124 -> 2040 | N18: ='GRUPA II'!G126 -> 1 | O18: =(I18+K18+M18) -> 7220 | P18: =(J18+L18+N18) -> 6 | Q18: =RANK(P18,$P$7:$P$33,1)+COUNTIFS($P$7:$P$33,P18,$O$7:$O$33,">"&O18) -> 1
A19: 13 | B19: =TABELA!H13 -> OMAR BAŠIĆ | F19: =TABELA!B13 -> SRK PLAVSKO JEZERO | I19: ='GRUPA II'!I36 -> 720 | J19: ='GRUPA II'!I37 -> 3 | K19: ='GRUPA II'!I80 -> 1340 | L19: ='GRUPA II'!I81 -> 7 | M19: ='GRUPA II'!I124 -> 0 | N19: ='GRUPA II'!I126 -> 9 | O19: =(I19+K19+M19) -> 2060 | P19: =(J19+L19+N19) -> 19 | Q19: =RANK(P19,$P$7:$P$33,1)+COUNTIFS($P$7:$P$33,P19,$O$7:$O$33,">"&O19) -> 21
A20: 14 | B20: =TABELA!H14 -> BALŠA FUŠTIĆ | F20: =TABELA!B14 -> SRFFK RAVNJAK - MOJKOVAC | I20: ='GRUPA II'!K36 -> 640 | J20: ='GRUPA II'!K37 -> 5 | K20: ='GRUPA II'!K80 -> 2200 | L20: ='GRUPA II'!K81 -> 3 | M20: ='GRUPA II'!K124 -> 700 | N20: ='GRUPA II'!K126 -> 3 | O20: =(I20+K20+M20) -> 3540 | P20: =(J20+L20+N20) -> 11 | Q20: =RANK(P20,$P$7:$P$33,1)+COUNTIFS($P$7:$P$33,P20,$O$7:$O$33,">"&O20) -> 7
A21: 15 | B21: =TABELA!H15 -> GORAN OBRENOVIĆ | F21: =TABELA!B15 -> SRFFK MANIRO - KOLAŠIN | I21: ='GRUPA II'!M36 -> 520 | J21: ='GRUPA II'!M37 -> 7 | K21: ='GRUPA II'!M80 -> 1440 | L21: ='GRUPA II'!M81 -> 6 | M21: ='GRUPA II'!M124 -> 1200 | N21: ='GRUPA II'!M126 -> 2 | O21: =(I21+K21+M21) -> 3160 | P21: =(J21+L21+N21) -> 15 | Q21: =RANK(P21,$P$7:$P$33,1)+COUNTIFS($P$7:$P$33,P21,$O$7:$O$33,">"&O21) -> 15
A22: 16 | B22: =TABELA!H16 -> PETAR OBRADOVIĆ | F22: =TABELA!B16 -> SRK VODENE LISICE - PODGORICA | I22: ='GRUPA II'!O36 -> 540 | J22: ='GRUPA II'!O37 -> 6 | K22: ='GRUPA II'!O80 -> 3520 | L22: ='GRUPA II'!O81 -> 1 | M22: ='GRUPA II'!O124 -> 0 | N22: ='GRUPA II'!O126 -> 9 | O22: =(I22+K22+M22) -> 4060 | P22: =(J22+L22+N22) -> 16 | Q22: =RANK(P22,$P$7:$P$33,1)+COUNTIFS($P$7:$P$33,P22,$O$7:$O$33,">"&O22) -> 16
A23: 17 | B23: =TABELA!H17 -> MEHMED DŽIDIĆ | F23: =TABELA!B17 -> SRK LIPLJEN - PLJEVLJA | I23: ='GRUPA II'!Q36 -> 720 | J23: ='GRUPA II'!Q37 -> 3 | K23: ='GRUPA II'!Q80 -> 2540 | L23: ='GRUPA II'!Q81 -> 2 | M23: ='GRUPA II'!Q124 -> 660 | N23: ='GRUPA II'!Q126 -> 5 | O23: =(I23+K23+M23) -> 3920 | P23: =(J23+L23+N23) -> 10 | Q23: =RANK(P23,$P$7:$P$33,1)+COUNTIFS($P$7:$P$33,P23,$O$7:$O$33,">"&O23) -> 5
A24: 18 | B24: =TABELA!H18 -> ARSO JEREMIĆ | F24: =TABELA!B18 -> SRK KOLAŠIN | I24: ='GRUPA II'!S36 -> 2480 | J24: ='GRUPA II'!S37 -> 2 | K24: ='GRUPA II'!S80 -> 760 | L24: ='GRUPA II'!S81 -> 8 | M24: ='GRUPA II'!S124 -> 700 | N24: ='GRUPA II'!S126 -> 3 | O24: =(I24+K24+M24) -> 3940 | P24: =(J24+L24+N24) -> 13 | Q24: =RANK(P24,$P$7:$P$33,1)+COUNTIFS($P$7:$P$33,P24,$O$7:$O$33,">"&O24) -> 10
A25: 19 | B25: =TABELA!K10 -> SAVO RAIČEVIĆ | F25: =TABELA!B10 -> SRK TARA - MOJKOVAC | I25: ='GRUPA III'!C36 -> 0 | J25: ='GRUPA III'!C37 -> 9 | K25: ='GRUPA III'!C80 -> 960 | L25: ='GRUPA III'!C81 -> 5 | M25: ='GRUPA III'!C124 -> 500 | N25: ='GRUPA III'!C125 -> 6 | O25: =(I25+K25+M25) -> 1460 | P25: =(J25+L25+N25) -> 20 | Q25: =RANK(P25,$P$7:$P$33,1)+COUNTIFS($P$7:$P$33,P25,$O$7:$O$33,">"&O25) -> 22
A26: 20 | B26: =TABELA!K11 -> NIKOLA TREBJEŠANIN | F26: =TABELA!B11 -> SRK GORŠTAK - KOLAŠIN | I26: ='GRUPA III'!E36 -> 640 | J26: ='GRUPA III'!E37 -> 4 | K26: ='GRUPA III'!E80 -> 600 | L26: ='GRUPA III'!E81 -> 8 | M26: ='GRUPA III'!E124 -> 640 | N26: ='GRUPA III'!E125 -> 5 | O26: =(I26+K26+M26) -> 1880 | P26: =(J26+L26+N26) -> 17 | Q26: =RANK(P26,$P$7:$P$33,1)+COUNTIFS($P$7:$P$33,P26,$O$7:$O$33,">"&O26) -> 19
A27: 21 | B27: =TABELA!K12 -> MILUN ĐUROVIĆ | F27: =TABELA!B12 -> SRK LIM - BERANE | I27: ='GRUPA III'!G36 -> 580 | J27: ='GRUPA III'!G37 -> 5 | K27: ='GRUPA III'!G80 -> 3460 | L27: ='GRUPA III'!G81 -> 1 | M27: ='GRUPA III'!G124 -> 4600 | N27: ='GRUPA III'!G125 -> 1 | O27: =(I27+K27+M27) -> 8640 | P27: =(J27+L27+N27) -> 7 | Q27: =RANK(P27,$P$7:$P$33,1)+COUNTIFS($P$7:$P$33,P27,$O$7:$O$33,">"&O27) -> 2
A28: 22 | B28: =TABELA!K13 -> DAMIR CANOVIĆ | F28: =TABELA!B13 -> SRK PLAVSKO JEZERO | I28: ='GRUPA III'!I36 -> 520 | J28: ='GRUPA III'!I37 -> 6 | K28: ='GRUPA III'!I80 -> 560 | L28: ='GRUPA III'!I81 -> 9 | M28: ='GRUPA III'!I124 -> 500 | N28: ='GRUPA III'!I125 -> 6 | O28: =(I28+K28+M28) -> 1580 | P28: =(J28+L28+N28) -> 21 | Q28: =RANK(P28,$P$7:$P$33,1)+COUNTIFS($P$7:$P$33,P28,$O$7:$O$33,">"&O28) -> 23
A29: 23 | B29: =TABELA!K14 -> ALEKSANDAR GAŠEVIĆ | F29: =TABELA!B14 -> SRFFK RAVNJAK - MOJKOVAC | I29: ='GRUPA III'!K36 -> 5040 | J29: ='GRUPA III'!K37 -> 1 | K29: ='GRUPA III'!K80 -> 2360 | L29: ='GRUPA III'!K81 -> 3 | M29: ='GRUPA III'!K124 -> 660 | N29: ='GRUPA III'!K125 -> 3 | O29: =(I29+K29+M29) -> 8060 | P29: =(J29+L29+N29) -> 7 | Q29: =RANK(P29,$P$7:$P$33,1)+COUNTIFS($P$7:$P$33,P29,$O$7:$O$33,">"&O29) -> 3
A30: 24 | B30: =TABELA!K15 -> BOGDAN MARKOVIĆ | F30: =TABELA!B15 -> SRFFK MANIRO - KOLAŠIN | I30: ='GRUPA III'!M36 -> 1800 | J30: ='GRUPA III'!M37 -> 3 | K30: ='GRUPA III'!M80 -> 640 | L30: ='GRUPA III'!M81 -> 7 | M30: ='GRUPA III'!M124 -> 660 | N30: ='GRUPA III'!M125 -> 3 | O30: =(I30+K30+M30) -> 3100 | P30: =(J30+L30+N30) -> 13 | Q30: =RANK(P30,$P$7:$P$33,1)+COUNTIFS($P$7:$P$33,P30,$O$7:$O$33,">"&O30) -> 12
A31: 25 | B31: =TABELA!K16 -> MARKO BAKIĆ | F31: =TABELA!B16 -> SRK VODENE LISICE - PODGORICA | I31: ='GRUPA III'!O36 -> 0 | J31: ='GRUPA III'!O37 -> 9 | K31: ='GRUPA III'!O80 -> 2580 | L31: ='GRUPA III'!O81 -> 2 | M31: ='GRUPA III'!O124 -> 1360 | N31: ='GRUPA III'!O125 -> 2 | O31: =(I31+K31+M31) -> 3940 | P31: =(J31+L31+N31) -> 13 | Q31: =RANK(P31,$P$7:$P$33,1)+COUNTIFS($P$7:$P$33,P31,$O$7:$O$33,">"&O31) -> 10
A32: 26 | B32: =TABELA!K17 -> MUMIN HEKALO | F32: =TABELA!B17 -> SRK LIPLJEN - PLJEVLJA | I32: ='GRUPA III'!Q36 -> 0 | J32: ='GRUPA III'!Q37 -> 9 | K32: ='GRUPA III'!Q80 -> 780 | L32: ='GRUPA III'!Q81 -> 6 | M32: ='GRUPA III'!Q124 -> 0 | N32: ='GRUPA III'!Q125 -> 9 | O32: =(I32+K32+M32) -> 780 | P32: =(J32+L32+N32) -> 24 | Q32: =RANK(P32,$P$7:$P$33,1)+COUNTIFS($P$7:$P$33,P32,$O$7:$O$33,">"&O32) -> 25
A33: 27 | B33: =TABELA!K18 -> IVICA RAJKOVIĆ | F33: =TABELA!B18 -> SRK KOLAŠIN | I33: ='GRUPA III'!S36 -> 3500 | J33: ='GRUPA III'!S37 -> 2 | K33: ='GRUPA III'!S80 -> 1440 | L33: ='GRUPA III'!S81 -> 4 | M33: ='GRUPA III'!S124 -> 0 | N33: ='GRUPA III'!S125 -> 9 | O33: =(I33+K33+M33) -> 4940 | P33: =(J33+L33+N33) -> 15 | Q33: =RANK(P33,$P$7:$P$33,1)+COUNTIFS($P$7:$P$33,P33,$O$7:$O$33,">"&O33) -> 14

Sheet EKIPNI PLASMAN
A2: MUŠIČARSKA LIGA CRNE GORE - EKIPNI REZULTATI
A3: Redni broj | B3: IME KLUBA | C3: TAKMIČAR GRUPA I UKUPNO POENA | D3: TAKMIČAR GRUPA I UKUPAN PLASMAN | E3: TAKMIČAR GRUPA II UKUPNO POENA | F3: TAKMIČAR GRUPA II UKUPAN PLASMAN | G3: TAKMIČAR GRUPA III UKUPNO POENA | H3: TAKMIČAR GRUPA III UKUPAN PLASMAN | I3: UKUPNO POENA | J3: ZBIR SEKTORSKIH PLASMANA | K3: UKUPAN PLASMAN
A4: 1 | B4: =TABELA!B10 -> SRK TARA - MOJKOVAC | C4: =POJEDINACNO!O7 -> 5700 | D4: =POJEDINACNO!P7 -> 12 | E4: =POJEDINACNO!O16 -> 1780 | F4: =POJEDINACNO!P16 -> 23 | G4: =POJEDINACNO!O25 -> 1460 | H4: =POJEDINACNO!P25 -> 20 | I4: =(C4+E4+G4) -> 8940 | J4: =(D4+F4+H4) -> 55 | K4: =RANK(J4,$J$4:$J$12,1)+COUNTIFS($J$4:$J$12,J4,$I$4:$I$12,">"&I4) -> 8
A5: 2 | B5: =TABELA!B11 -> SRK GORŠTAK - KOLAŠIN | C5: =POJEDINACNO!O8 -> 7000 | D5: =POJEDINACNO!P8 -> 11 | E5: =POJEDINACNO!O17 -> 520 | F5: =POJEDINACNO!P17 -> 27 | G5: =POJEDINACNO!O26 -> 1880 | H5: =POJEDINACNO!P26 -> 17 | I5: =(C5+E5+G5) -> 9400 | J5: =(D5+F5+H5) -> 55 | K5: =RANK(J5,$J$4:$J$12,1)+COUNTIFS($J$4:$J$12,J5,$I$4:$I$12,">"&I5) -> 7
A6: 3 | B6: =TABELA!B12 -> SRK LIM - BERANE | C6: =POJEDINACNO!O9 -> 4840 | D6: =POJEDINACNO!P9 -> 12 | E6: =POJEDINACNO!O18 -> 7220 | F6: =POJEDINACNO!P18 -> 6 | G6: =POJEDINACNO!O27 -> 8640 | H6: =POJEDINACNO!P27 -> 7 | I6: =(C6+E6+G6) -> 20700 | J6: =(D6+F6+H6) -> 25 | K6: =RANK(J6,$J$4:$J$12,1)+COUNTIFS($J$4:$J$12,J6,$I$4:$I$12,">"&I6) -> 1
A7: 4 | B7: =TABELA!B13 -> SRK PLAVSKO JEZERO | C7: =POJEDINACNO!O10 -> 0 | D7: =POJEDINACNO!P10 -> 27 | E7: =POJEDINACNO!O19 -> 2060 | F7: =POJEDINACNO!P19 -> 19 | G7: =POJEDINACNO!O28 -> 1580 | H7: =POJEDINACNO!P28 -> 21 | I7: =(C7+E7+G7) -> 3640 | J7: =(D7+F7+H7) -> 67 | K7: =RANK(J7,$J$4:$J$12,1)+COUNTIFS($J$4:$J$12,J7,$I$4:$I$12,">"&I7) -> 9
A8: 5 | B8: =TABELA!B14 -> SRFFK RAVNJAK - MOJKOVAC | C8: =POJEDINACNO!O11 -> 4520 | D8: =POJEDINACNO!P11 -> 14 | E8: =POJEDINACNO!O20 -> 3540 | F8: =POJEDINACNO!P20 -> 11 | G8: =POJEDINACNO!O29 -> 8060 | H8: =POJEDINACNO!P29 -> 7 | I8: =(C8+E8+G8) -> 16120 | J8: =(D8+F8+H8) -> 32 | K8: =RANK(J8,$J$4:$J$12,1)+COUNTIFS($J$4:$J$12,J8,$I$4:$I$12,">"&I8) -> 2
A9: 6 | B9: =TABELA!B15 -> SRFFK MANIRO - KOLAŠIN | C9: =POJEDINACNO!O12 -> 8000 | D9: =POJEDINACNO!P12 -> 8 | E9: =POJEDINACNO!O21 -> 3160 | F9: =POJEDINACNO!P21 -> 15 | G9: =POJEDINACNO!O30 -> 3100 | H9: =POJEDINACNO!P30 -> 13 | I9: =(C9+E9+G9) -> 14260 | J9: =(D9+F9+H9) -> 36 | K9: =RANK(J9,$J$4:$J$12,1)+COUNTIFS($J$4:$J$12,J9,$I$4:$I$12,">"&I9) -> 3
A10: 7 | B10: =TABELA!B16 -> SRK VODENE LISICE - PODGORICA | C10: =POJEDINACNO!O13 -> 3100 | D10: =POJEDINACNO!P13 -> 19 | E10: =POJEDINACNO!O22 -> 4060 | F10: =POJEDINACNO!P22 -> 16 | G10: =POJEDINACNO!O31 -> 3940 | H10: =POJEDINACNO!P31 -> 13 | I10: =(C10+E10+G10) -> 11100 | J10: =(D10+F10+H10) -> 48 | K10: =RANK(J10,$J$4:$J$12,1)+COUNTIFS($J$4:$J$12,J10,$I$4:$I$12,">"&I10) -> 5
A11: 8 | B11: =TABELA!B17 -> SRK LIPLJEN - PLJEVLJA | C11: =POJEDINACNO!O14 -> 3560 | D11: =POJEDINACNO!P14 -> 17 | E11: =POJEDINACNO!O23 -> 3920 | F11: =POJEDINACNO!P23 -> 10 | G11: =POJEDINACNO!O32 -> 780 | H11: =POJEDINACNO!P32 -> 24 | I11: =(C11+E11+G11) -> 8260 | J11: =(D11+F11+H11) -> 51 | K11: =RANK(J11,$J$4:$J$12,1)+COUNTIFS($J$4:$J$12,J11,$I$4:$I$12,">"&I11) -> 6
A12: 9 | B12: =TABELA!B18 -> SRK KOLAŠIN | C12: =POJEDINACNO!O15 -> 3100 | D12: =POJEDINACNO!P15 -> 16 | E12: =POJEDINACNO!O24 -> 3940 | F12: =POJEDINACNO!P24 -> 13 | G12: =POJEDINACNO!O33 -> 4940 | H12: =POJEDINACNO!P33 -> 15 | I12: =(C12+E12+G12) -> 11980 | J12: =(D12+F12+H12) -> 44 | K12: =RANK(J12,$J$4:$J$12,1)+COUNTIFS($J$4:$J$12,J12,$I$4:$I$12,">"&I12) -> 4
B15: S T A T I S T I K A
B16: UKUPNO ULOVLJENIH RIBA U KOLU | C16: =SUM('GRUPA I'!C38:C40,'GRUPA I'!E38:E40,'GRUPA I'!G38:G40,'GRUPA I'!I38:I40,'GRUPA I'!K38:K40,'GRUPA I'!M38:M40,'GRUPA I'!O38:O40,'GRUPA I'!Q38:Q40,'GRUPA I'!S38:S40,'GRUPA I'!C83:C85,'GRUPA I'!E83:E85,'GRUPA I'!G83:G85,'GRUPA I'!I83:I85,'GRUPA I'!K83:K85,'GRUPA I'!M83:M85,'GRUPA I'!O83:O85,'GRUPA I'!Q83:Q85,'GRUPA I'!S83:S85,'GRUPA I'!C126:C128,'GRUPA I'!E126:E128,'GRUPA I'!F126:F128,'GRUPA I'!G126:G128,'GRUPA I'!I126:I128,'GRUPA I'!K126:K128,'GRUPA I'!M126:M128,'GRUPA I'!O126:O128,'GRUPA I'!Q126:Q128,'GRUPA I'!S126:S128,'GRUPA II'!C38:C40,'GRUPA II'!E38:E40,'GRUPA II'!G38:G40,'GRUPA II'!I38:I40,'GRUPA II'!K38:K40,'GRUPA II'!M38:M40,'GRUPA II'!O38:O40,'GRUPA II'!Q38:Q40,'GRUPA II'!S38:S40,'GRUPA II'!C82:C84,'GRUPA II'!E82:E84,'GRUPA II'!G82:G84,'GRUPA II'!I82:I84,'GRUPA II'!K82:K84,'GRUPA II'!M82:M84,'GRUPA II'!O82:O84,'GRUPA II'!Q82:Q84,'GRUPA II'!S82:S84,'GRUPA II'!C127:C129,'GRUPA II'!E127:E129,'GRUPA II'!G127:G129,'GRUPA II'!I127:I129,'GRUPA II'!K127:K129,'GRUPA II'!M127:M129,'GRUPA II'!O127:O129,'GRUPA II'!Q127:Q129,'GRUPA II'!S127:S129,'GRUPA III'!C38:C40,'GRUPA III'!E38:E40,'GRUPA III'!G38:G40,'GRUPA III'!I38:I40,'GRUPA III'!K38:K40,'GRUPA III'!M38:M40,'GRUPA III'!O38:O40,'GRUPA III'!Q38:Q40,'GRUPA III'!S38:S40,'GRUPA III'!C82:C84,'GRUPA III'!E82:E84,'GRUPA III'!G82:G84,'GRUPA III'!I82:I84,'GRUPA III'!K82:K84,'GRUPA III'!M82:M84,'GRUPA III'!O82:O84,'GRUPA III'!Q82:Q84,'GRUPA III'!S82:S84,'GRUPA III'!C126:C128,'GRUPA III'!E126:E128,'GRUPA III'!G126:G128,'GRUPA III'!I126:I128,'GRUPA III'!K126:K128,'GRUPA III'!M126:M128,'GRUPA III'!O126:O128,'GRUPA III'!Q126:Q128,'GRUPA III'!S126:S128,) -> 161
B17: NAJDUŽA IZMJERENA RIBA KOLA | C17: =MAX('GRUPA I'!C41,'GRUPA I'!E41,'GRUPA I'!G41,'GRUPA I'!I41,'GRUPA I'!K41,'GRUPA I'!M41,'GRUPA I'!O41,'GRUPA I'!Q41,'GRUPA I'!S41,'GRUPA I'!C86,'GRUPA I'!E86,'GRUPA I'!G86,'GRUPA I'!I86,'GRUPA I'!K86,'GRUPA I'!M86,'GRUPA I'!O86,'GRUPA I'!Q86,'GRUPA I'!S86,'GRUPA I'!C129,'GRUPA I'!E129,'GRUPA I'!G129,'GRUPA I'!I129,'GRUPA I'!K129,'GRUPA I'!M129,'GRUPA I'!O129,'GRUPA I'!Q129,'GRUPA I'!S129,'GRUPA II'!C41,'GRUPA II'!E41,'GRUPA II'!G41,'GRUPA II'!I41,'GRUPA II'!K41,'GRUPA II'!M41,'GRUPA II'!O41,'GRUPA II'!Q41,'GRUPA II'!S41,'GRUPA II'!C85,'GRUPA II'!E85,'GRUPA II'!G85,'GRUPA II'!I85,'GRUPA II'!K85,'GRUPA II'!M85,'GRUPA II'!O85,'GRUPA II'!Q85,'GRUPA II'!S85,'GRUPA II'!C130,'GRUPA II'!E130,'GRUPA II'!G130,'GRUPA II'!I130,'GRUPA II'!K130,'GRUPA II'!M130,'GRUPA II'!O130,'GRUPA II'!Q130,'GRUPA II'!S130,'GRUPA III'!C41,'GRUPA III'!E41,'GRUPA III'!G41,'GRUPA III'!I41,'GRUPA III'!K41,'GRUPA III'!M41,'GRUPA III'!O41,'GRUPA III'!Q41,'GRUPA III'!S41,'GRUPA III'!C85,'GRUPA III'!E85,'GRUPA III'!G85,'GRUPA III'!I85,'GRUPA III'!K85,'GRUPA III'!M85,'GRUPA III'!O85,'GRUPA III'!Q85,'GRUPA III'!S85,'GRUPA III'!C129,'GRUPA III'!E129,'GRUPA III'!G129,'GRUPA III'!I129,'GRUPA III'!K129,'GRUPA III'!M129,'GRUPA III'!O129,'GRUPA III'!Q129,'GRUPA III'!S129,) -> 45
